Workbook

Sheet update
A1: UPDATE TIME | B1: UPDATE | C1: 更新内容
A2: 44834 | C2: 基于北斗整理大货与散件清单给LMR
A3: 44858 | C3: 北斗国家为FR的大货不全，重新结合GOMS补充清单
A4: 44918 | C4: S7 PRO的适配器
A5: 44979 | C5: 增加S7 Premium，DE线下型号，清单同S7 PRO
C6: 增加iFloor 2 Plus，DE/FR线下型号，清单同iFloor 2
C7: 增加iFloor Breeze Essentials，DE线下型号，清单同iFloor Breeze
C8: 增加S5、S5 Pro 2降本版
C9: 增加近期新搭散件，会陆续到货
A10: 45007 | C10: 增加PURE ONE Air、PURE ONE AIR PET & PRO
A11: 45043 | C11: 增加回收桶盖组件，适用于S7系列
C12: 增加S6
A13: 45086 | C13: 增加2011地刷电机（和I3S3通用）
C14: 增加hepa滚刷套装的彩盒版，适用于S7系列
C15: 增加地毯机的滚刷盖清理附件
C16: 增加iFloor 2的回收桶，重新搭了一个SKU
A17: 45089 | C17: 更新S6清单：hepa、滚刷、滚刷电机、蠕动泵
A18: 45141 | C18: 更新CL1879P-01，S3 Breeze的电机
A19: 45156 | C19: 增加S6清单：小轮、附件支架组合、地刷主控板
A20: 45161 | C20: 增加新品S7 Steam清单
A21: 45173 | C21: 增加PURE ONE STATION PET、S7 Steam Plus清单
A22: 45175 | C22: 增加S7 Combo散件清单
A23: 45188 | C23: 增加S5 Pro清单
A24: 45210 | C24: 增加S6 Pet清单
A25: 45225 | C25: 增加S5系列机身信号组件（带pin针的机身导电散件）
C26: 增加欧版S11降本款（大货SKU不变）散件：主机、电池、尘桶
C27: 增加地毯机降本款（大货SKU不变）散件：显示屏、PCBA
A28: 45351 | C28: 增加CL2371 S5标准化清单：CL2371A-01、CL2371A-02
A29: 45363 | C29: 增加CL2316 Switch S6清单：CL2316G-01、CL2316G-02
A30: 45365 | C30: 增加CL2331 S6标准化清单：CL2331I-01、CL2331K-02
C31: 增加CL2347 iFloor 5系列清单：CL2347C-01、CL2347C-02、CL2347B-01
C32: 增加CL2335 S7 Pro标准化清单：CL2335E-01、CL2335G-01
C33: 增加CL2220 Switch S7清单：CL2220H-01
A34: 45372 | C34: 增加CL2041 Ifloor 2系列改型清单：CL2041B-03、CL2041B-04
C35: 增加CL2328 Stretch S6清单：CL2328C-01
C36: 增加CL2020 S5 COMBO系列的机身充电装配组件：9FWRI150300，1月下单，预计6月初到PST&LMR
C37: 增加CL2011系列的机身充电导线组件：9FWRI040000，3月下单，预计7月到PST&LMR
C38: 增加CL2123系列的机体上装饰盖+机体后盖（9FWRH200300+9FWRH200400），3月下单，预计7月到PST&LMR
A39: 45410 | C39: 增加CL2335E-01 S7 Pro标准化的适配器
A40: 45433 | C40: 增加S5标准化/S6标准化回收桶上盖组件9FWRH130100
...

Sheet EU SP list
A1: 更新时间 UPDATE TIME | B1: FG SKU | C1: 大货FG ID | D1: 系列型号 | E1: 大货国家COUNTRY | F1: 大货销售型号FG NAME | G1: FG EAN CODE | H1: 大货颜色COLOR | I1: 大货状态 | J1: 箱毛重(千克) Gross weight (KG) | K1: 外箱包装尺寸(MM)长/Package MM Length | L1: 外箱包装尺寸(MM)宽/Package MM Width | M1: 外箱包装尺寸(MM)高/Package MM Height | N1: SP SKU | O1: 迭代 Spare part substitute | P1: 散件老 OLD SAP ID | Q1: 散件新SAP ID | R1: SP DES | S1: PICTURE LINK | T1: NOTE | U1: 中文描述DES | V1: SP EAN CODE
A2: 46169 | B2: FW770100DE | C2: =VLOOKUP(B2,'大货清单（不定期按GOMS更新）'!A:H,8,0) -> 109-24281001 | D2: =VLOOKUP(B2,'大货清单（不定期按GOMS更新）'!A:C,3,0) -> CL2428J-01 | E2: =VLOOKUP(B2,'大货清单（不定期按GOMS更新）'!A:H,4,0) -> DE | F2: =VLOOKUP(B2,'大货清单（不定期按GOMS更新）'!A:H,2,0) -> Floor One Station S9 Scientist | G2: =VLOOKUP(B2,'大货清单（不定期按GOMS更新）'!A:I,9,FALSE) -> 6971745581557 | H2: =VLOOKUP(B2,'大货清单（不定期按GOMS更新）'!A:H,7,0) -> Gray | I2: =VLOOKUP(B2,'大货清单（不定期按GOMS更新）'!A:F,6,FALSE) -> GTM | J2: =VLOOKUP(B2,'大货清单（不定期按GOMS更新）'!A:K,11,FALSE) -> 14.3 | K2: =VLOOKUP(B2,'大货清单（不定期按GOMS更新）'!A:N,12,FALSE) -> 785 | L2: =VLOOKUP(B2,'大货清单（不定期按GOMS更新）'!A:M,13,FALSE) -> 386 | M2: =VLOOKUP(B2,'大货清单（不定期按GOMS更新）'!A:N,14,FALSE) -> 367 | N2: 9FWBC510000 | O2: =IFERROR(VLOOKUP(N2,'散件迭代（不定期更新）'!C:J,8,FALSE),0) -> 0 | P2: =IFERROR(VLOOKUP(N2,'散件（更新）'!B:H,3,FALSE),0) | Q2: =VLOOKUP(N2,'散件（更新）'!B:H,2,FALSE) -> 114-24280313 | R2: =VLOOKUP(N2,'散件（更新）'!B:H,7,FALSE) -> Brush Roller Cover | S2: =VLOOKUP(N2,'散件（更新）'!B:E,4,FALSE) -> https://tineco-yxzt.oss-accelerate.aliyuncs.com/20260210/gunshuagaizujian_1770686015747.png | U2: =VLOOKUP(N2,'散件（更新）'!B:G,6,FALSE) -> SP;CL2428C-01;滚刷盖组件 | V2: =VLOOKUP(N2,'散件（更新）'!B:I,8,FALSE) -> 6932485020737
A3: 46169 | B3: FW770100DE | C3: =VLOOKUP(B3,'大货清单（不定期按GOMS更新）'!A:H,8,0) -> 109-24281001 | D3: =VLOOKUP(B3,'大货清单（不定期按GOMS更新）'!A:C,3,0) -> CL2428J-01 | E3: =VLOOKUP(B3,'大货清单（不定期按GOMS更新）'!A:H,4,0) -> DE | F3: =VLOOKUP(B3,'大货清单（不定期按GOMS更新）'!A:H,2,0) -> Floor One Station S9 Scientist | G3: =VLOOKUP(B3,'大货清单（不定期按GOMS更新）'!A:I,9,FALSE) -> 6971745581557 | H3: =VLOOKUP(B3,'大货清单（不定期按GOMS更新）'!A:H,7,0) -> Gray | I3: =VLOOKUP(B3,'大货清单（不定期按GOMS更新）'!A:F,6,FALSE) -> GTM | J3: =VLOOKUP(B3,'大货清单（不定期按GOMS更新）'!A:K,11,FALSE) -> 14.3 | K3: =VLOOKUP(B3,'大货清单（不定期按GOMS更新）'!A:N,12,FALSE) -> 785 | L3: =VLOOKUP(B3,'大货清单（不定期按GOMS更新）'!A:M,13,FALSE) -> 386 | M3: =VLOOKUP(B3,'大货清单（不定期按GOMS更新）'!A:N,14,FALSE) -> 367 | N3: 9FWBR060000 | O3: =IFERROR(VLOOKUP(N3,'散件迭代（不定期更新）'!C:J,8,FALSE),0) -> 0 | P3: =IFERROR(VLOOKUP(N3,'散件（更新）'!B:H,3,FALSE),0) | Q3: =VLOOKUP(N3,'散件（更新）'!B:H,2,FALSE) -> 114-23761801 | R3: =VLOOKUP(N3,'散件（更新）'!B:H,7,FALSE) -> Brush Roller | S3: =VLOOKUP(N3,'散件（更新）'!B:E,4,FALSE) -> https://tineco-yxzt.oss-accelerate.aliyuncs.com/20241219/weixintupian_20241114110949_1734578233397.jpg | U3: =VLOOKUP(N3,'散件（更新）'!B:G,6,FALSE) -> 耐热滚刷组件 | V3: =VLOOKUP(N3,'散件（更新）'!B:I,8,FALSE) -> 6932485002405
A4: 46169 | B4: FW770100DE | C4: =VLOOKUP(B4,'大货清单（不定期按GOMS更新）'!A:H,8,0) -> 109-24281001 | D4: =VLOOKUP(B4,'大货清单（不定期按GOMS更新）'!A:C,3,0) -> CL2428J-01 | E4: =VLOOKUP(B4,'大货清单（不定期按GOMS更新）'!A:H,4,0) -> DE | F4: =VLOOKUP(B4,'大货清单（不定期按GOMS更新）'!A:H,2,0) -> Floor One Station S9 Scientist | G4: =VLOOKUP(B4,'大货清单（不定期按GOMS更新）'!A:I,9,FALSE) -> 6971745581557 | H4: =VLOOKUP(B4,'大货清单（不定期按GOMS更新）'!A:H,7,0) -> Gray | I4: =VLOOKUP(B4,'大货清单（不定期按GOMS更新）'!A:F,6,FALSE) -> GTM | J4: =VLOOKUP(B4,'大货清单（不定期按GOMS更新）'!A:K,11,FALSE) -> 14.3 | K4: =VLOOKUP(B4,'大货清单（不定期按GOMS更新）'!A:N,12,FALSE) -> 785 | L4: =VLOOKUP(B4,'大货清单（不定期按GOMS更新）'!A:M,13,FALSE) -> 386 | M4: =VLOOKUP(B4,'大货清单（不定期按GOMS更新）'!A:N,14,FALSE) -> 367 | N4: 9FWRH4A0000 | O4: =IFERROR(VLOOKUP(N4,'散件迭代（不定期更新）'!C:J,8,FALSE),0) -> 0 | P4: =IFERROR(VLOOKUP(N4,'散件（更新）'!B:H,3,FALSE),0) -> 0 | Q4: =VLOOKUP(N4,'散件（更新）'!B:H,2,FALSE) -> 114-25350310 | R4: =VLOOKUP(N4,'散件（更新）'!B:H,7,FALSE) -> Water Spray Board Assembly | S4: =VLOOKUP(N4,'散件（更新）'!B:E,4,FALSE) -> https://tineco-yxzt.oss-accelerate.aliyuncs.com/20250912/f9161366-0e5d-47c3-addb-11f9dd397021_1757660382417.png | U4: =VLOOKUP(N4,'散件（更新）'!B:G,6,FALSE) -> SP;CL2535C-01;喷水板超声组件 | V4: =VLOOKUP(N4,'散件（更新）'!B:I,8,FALSE) -> 6932485013623
A5: 46169 | B5: FW770100DE | C5: =VLOOKUP(B5,'大货清单（不定期按GOMS更新）'!A:H,8,0) -> 109-24281001 | D5: =VLOOKUP(B5,'大货清单（不定期按GOMS更新）'!A:C,3,0) -> CL2428J-01 | E5: =VLOOKUP(B5,'大货清单（不定期按GOMS更新）'!A:H,4,0) -> DE | F5: =VLOOKUP(B5,'大货清单（不定期按GOMS更新）'!A:H,2,0) -> Floor One Station S9 Scientist | G5: =VLOOKUP(B5,'大货清单（不定期按GOMS更新）'!A:I,9,FALSE) -> 6971745581557 | H5: =VLOOKUP(B5,'大货清单（不定期按GOMS更新）'!A:H,7,0) -> Gray | I5: =VLOOKUP(B5,'大货清单（不定期按GOMS更新）'!A:F,6,FALSE) -> GTM | J5: =VLOOKUP(B5,'大货清单（不定期按GOMS更新）'!A:K,11,FALSE) -> 14.3 | K5: =VLOOKUP(B5,'大货清单（不定期按GOMS更新）'!A:N,12,FALSE) -> 785 | L5: =VLOOKUP(B5,'大货清单（不定期按GOMS更新）'!A:M,13,FALSE) -> 386 | M5: =VLOOKUP(B5,'大货清单（不定期按GOMS更新）'!A:N,14,FALSE) -> 367 | N5: 9FWRH4A0100 | O5: =IFERROR(VLOOKUP(N5,'散件迭代（不定期更新）'!C:J,8,FALSE),0) -> 0 | P5: =IFERROR(VLOOKUP(N5,'散件（更新）'!B:H,3,FALSE),0) -> 0 | Q5: =VLOOKUP(N5,'散件（更新）'!B:H,2,FALSE) -> 114-25350311 | R5: =VLOOKUP(N5,'散件（更新）'!B:H,7,FALSE) -> Brush Roller Assembly Upper Cover + seals | S5: =VLOOKUP(N5,'散件（更新）'!B:E,4,FALSE) -> https://tineco-yxzt.oss-accelerate.aliyuncs.com/20250912/332BFB7995C732A1F3131A70178CB908_1757660473209.png | T5: substitute: new version, same stucture 9FWBC220000 | U5: =VLOOKUP(N5,'散件（更新）'!B:G,6,FALSE) -> SP;CL2535C-01;地刷上盖包胶组件+密封条 | V5: =VLOOKUP(N5,'散件（更新）'!B:I,8,FALSE) -> 6932485013630
A6: 46169 | B6: FW770100DE | C6: =VLOOKUP(B6,'大货清单（不定期按GOMS更新）'!A:H,8,0) -> 109-24281001 | D6: =VLOOKUP(B6,'大货清单（不定期按GOMS更新）'!A:C,3,0) -> CL2428J-01 | E6: =VLOOKUP(B6,'大货清单（不定期按GOMS更新）'!A:H,4,0) -> DE | F6: =VLOOKUP(B6,'大货清单（不定期按GOMS更新）'!A:H,2,0) -> Floor One Station S9 Scientist | G6: =VLOOKUP(B6,'大货清单（不定期按GOMS更新）'!A:I,9,FALSE) -> 6971745581557 | H6: =VLOOKUP(B6,'大货清单（不定期按GOMS更新）'!A:H,7,0) -> Gray | I6: =VLOOKUP(B6,'大货清单（不定期按GOMS更新）'!A:F,6,FALSE) -> GTM | J6: =VLOOKUP(B6,'大货清单（不定期按GOMS更新）'!A:K,11,FALSE) -> 14.3 | K6: =VLOOKUP(B6,'大货清单（不定期按GOMS更新）'!A:N,12,FALSE) -> 785 | L6: =VLOOKUP(B6,'大货清单（不定期按GOMS更新）'!A:M,13,FALSE) -> 386 | M6: =VLOOKUP(B6,'大货清单（不定期按GOMS更新）'!A:N,14,FALSE) -> 367 | N6: 9FWRH4A1000 | O6: =IFERROR(VLOOKUP(N6,'散件迭代（不定期更新）'!C:J,8,FALSE),0) -> 0 | P6: =IFERROR(VLOOKUP(N6,'散件（更新）'!B:H,3,FALSE),0) -> 0 | Q6: =VLOOKUP(N6,'散件（更新）'!B:H,2,FALSE) -> 114-25350331 | R6: =VLOOKUP(N6,'散件（更新）'!B:H,7,FALSE) -> Connector Assembly＋Buckle | S6: =VLOOKUP(N6,'散件（更新）'!B:E,4,FALSE) -> 0 | U6: =VLOOKUP(N6,'散件（更新）'!B:G,6,FALSE) -> SP;CL2535C-02;转接头组件+锁扣 | V6: =VLOOKUP(N6,'散件（更新）'!B:I,8,FALSE) -> 6932485014354
A7: 46169 | B7: FW770100DE | C7: =VLOOKUP(B7,'大货清单（不定期按GOMS更新）'!A:H,8,0) -> 109-24281001 | D7: =VLOOKUP(B7,'大货清单（不定期按GOMS更新）'!A:C,3,0) -> CL2428J-01 | E7: =VLOOKUP(B7,'大货清单（不定期按GOMS更新）'!A:H,4,0) -> DE | F7: =VLOOKUP(B7,'大货清单（不定期按GOMS更新）'!A:H,2,0) -> Floor One Station S9 Scientist | G7: =VLOOKUP(B7,'大货清单（不定期按GOMS更新）'!A:I,9,FALSE) -> 6971745581557 | H7: =VLOOKUP(B7,'大货清单（不定期按GOMS更新）'!A:H,7,0) -> Gray | I7: =VLOOKUP(B7,'大货清单（不定期按GOMS更新）'!A:F,6,FALSE) -> GTM | J7: =VLOOKUP(B7,'大货清单（不定期按GOMS更新）'!A:K,11,FALSE) -> 14.3 | K7: =VLOOKUP(B7,'大货清单（不定期按GOMS更新）'!A:N,12,FALSE) -> 785 | L7: =VLOOKUP(B7,'大货清单（不定期按GOMS更新）'!A:M,13,FALSE) -> 386 | M7: =VLOOKUP(B7,'大货清单（不定期按GOMS更新）'!A:N,14,FALSE) -> 367 | N7: 9FWRH510000 | O7: =IFERROR(VLOOKUP(N7,'散件迭代（不定期更新）'!C:J,8,FALSE),0) -> 0 | P7: =IFERROR(VLOOKUP(N7,'散件（更新）'!B:H,3,FALSE),0) | Q7: =VLOOKUP(N7,'散件（更新）'!B:H,2,FALSE) -> 114-24280300 | R7: =VLOOKUP(N7,'散件（更新）'!B:H,7,FALSE) -> Light Panel Assembly | S7: =VLOOKUP(N7,'散件（更新）'!B:E,4,FALSE) -> https://tineco-yxzt.oss-accelerate.aliyuncs.com/20260209/CL2428zhaomingbanzujian_1770623014213.png | U7: =VLOOKUP(N7,'散件（更新）'!B:G,6,FALSE) -> SP;CL2428C-01;CL2428照明板组件 | V7: =VLOOKUP(N7,'散件（更新）'!B:I,8,FALSE) -> 6932485020607
A8: 46169 | B8: FW770100DE | C8: =VLOOKUP(B8,'大货清单（不定期按GOMS更新）'!A:H,8,0) -> 109-24281001 | D8: =VLOOKUP(B8,'大货清单（不定期按GOMS更新）'!A:C,3,0) -> CL2428J-01 | E8: =VLOOKUP(B8,'大货清单（不定期按GOMS更新）'!A:H,4,0) -> DE | F8: =VLOOKUP(B8,'大货清单（不定期按GOMS更新）'!A:H,2,0) -> Floor One Station S9 Scientist | G8: =VLOOKUP(B8,'大货清单（不定期按GOMS更新）'!A:I,9,FALSE) -> 6971745581557 | H8: =VLOOKUP(B8,'大货清单（不定期按GOMS更新）'!A:H,7,0) -> Gray | I8: =VLOOKUP(B8,'大货清单（不定期按GOMS更新）'!A:F,6,FALSE) -> GTM | J8: =VLOOKUP(B8,'大货清单（不定期按GOMS更新）'!A:K,11,FALSE) -> 14.3 | K8: =VLOOKUP(B8,'大货清单（不定期按GOMS更新）'!A:N,12,FALSE) -> 785 | L8: =VLOOKUP(B8,'大货清单（不定期按GOMS更新）'!A:M,13,FALSE) -> 386 | M8: =VLOOKUP(B8,'大货清单（不定期按GOMS更新）'!A:N,14,FALSE) -> 367 | N8: 9FWRH510300 | O8: =IFERROR(VLOOKUP(N8,'散件迭代（不定期更新）'!C:J,8,FALSE),0) -> 0 | P8: =IFERROR(VLOOKUP(N8,'散件（更新）'!B:H,3,FALSE),0) | Q8: =VLOOKUP(N8,'散件（更新）'!B:H,2,FALSE) -> 114-24280309 | R8: =VLOOKUP(N8,'散件（更新）'!B:H,7,FALSE) -> Right Decorative Cover | S8: =VLOOKUP(N8,'散件（更新）'!B:E,4,FALSE) -> https://tineco-yxzt.oss-accelerate.aliyuncs.com/20260210/jishenyouzhuangshigai_1770685846886.png | U8: =VLOOKUP(N8,'散件（更新）'!B:G,6,FALSE) -> SP;CL2428C-01;机身右装饰盖 | V8: =VLOOKUP(N8,'散件（更新）'!B:I,8,FALSE) -> 6932485020690
A9: 46169 | B9: FW770100DE | C9: =VLOOKUP(B9,'大货清单（不定期按GOMS更新）'!A:H,8,0) -> 109-24281001 | D9: =VLOOKUP(B9,'大货清单（不定期按GOMS更新）'!A:C,3,0) -> CL2428J-01 | E9: =VLOOKUP(B9,'大货清单（不定期按GOMS更新）'!A:H,4,0) -> DE | F9: =VLOOKUP(B9,'大货清单（不定期按GOMS更新）'!A:H,2,0) -> Floor One Station S9 Scientist | G9: =VLOOKUP(B9,'大货清单（不定期按GOMS更新）'!A:I,9,FALSE) -> 6971745581557 | H9: =VLOOKUP(B9,'大货清单（不定期按GOMS更新）'!A:H,7,0) -> Gray | I9: =VLOOKUP(B9,'大货清单（不定期按GOMS更新）'!A:F,6,FALSE) -> GTM | J9: =VLOOKUP(B9,'大货清单（不定期按GOMS更新）'!A:K,11,FALSE) -> 14.3 | K9: =VLOOKUP(B9,'大货清单（不定期按GOMS更新）'!A:N,12,FALSE) -> 785 | L9: =VLOOKUP(B9,'大货清单（不定期按GOMS更新）'!A:M,13,FALSE) -> 386 | M9: =VLOOKUP(B9,'大货清单（不定期按GOMS更新）'!A:N,14,FALSE) -> 367 | N9: 9FWRH510400 | O9: =IFERROR(VLOOKUP(N9,'散件迭代（不定期更新）'!C:J,8,FALSE),0) -> 0 | P9: =IFERROR(VLOOKUP(N9,'散件（更新）'!B:H,3,FALSE),0) | Q9: =VLOOKUP(N9,'散件（更新）'!B:H,2,FALSE) -> 114-24280310 | R9: =VLOOKUP(N9,'散件（更新）'!B:H,7,FALSE) -> Left Decorative Cover | S9: =VLOOKUP(N9,'散件（更新）'!B:E,4,FALSE) -> https://tineco-yxzt.oss-accelerate.aliyuncs.com/20260210/jishenzuozhuangshigai_1770685879246.png | U9: =VLOOKUP(N9,'散件（更新）'!B:G,6,FALSE) -> SP;CL2428C-01;机身左装饰盖 | V9: =VLOOKUP(N9,'散件（更新）'!B:I,8,FALSE) -> 6932485020706
A10: 46169 | B10: FW770100DE | C10: =VLOOKUP(B10,'大货清单（不定期按GOMS更新）'!A:H,8,0) -> 109-24281001 | D10: =VLOOKUP(B10,'大货清单（不定期按GOMS更新）'!A:C,3,0) -> CL2428J-01 | E10: =VLOOKUP(B10,'大货清单（不定期按GOMS更新）'!A:H,4,0) -> DE | F10: =VLOOKUP(B10,'大货清单（不定期按GOMS更新）'!A:H,2,0) -> Floor One Station S9 Scientist | G10: =VLOOKUP(B10,'大货清单（不定期按GOMS更新）'!A:I,9,FALSE) -> 6971745581557 | H10: =VLOOKUP(B10,'大货清单（不定期按GOMS更新）'!A:H,7,0) -> Gray | I10: =VLOOKUP(B10,'大货清单（不定期按GOMS更新）'!A:F,6,FALSE) -> GTM | J10: =VLOOKUP(B10,'大货清单（不定期按GOMS更新）'!A:K,11,FALSE) -> 14.3 | K10: =VLOOKUP(B10,'大货清单（不定期按GOMS更新）'!A:N,12,FALSE) -> 785 | L10: =VLOOKUP(B10,'大货清单（不定期按GOMS更新）'!A:M,13,FALSE) -> 386 | M10: =VLOOKUP(B10,'大货清单（不定期按GOMS更新）'!A:N,14,FALSE) -> 367 | N10: 9FWRH510600 | O10: =IFERROR(VLOOKUP(N10,'散件迭代（不定期更新）'!C:J,8,FALSE),0) -> 0 | P10: =IFERROR(VLOOKUP(N10,'散件（更新）'!B:H,3,FALSE),0) | Q10: =VLOOKUP(N10,'散件（更新）'!B:H,2,FALSE) -> 114-24280319 | R10: =VLOOKUP(N10,'散件（更新）'!B:H,7,FALSE) -> Rear Cover Screw Plug Assembly | S10: =VLOOKUP(N10,'散件（更新）'!B:E,4,FALSE) -> https://tineco-yxzt.oss-accelerate.aliyuncs.com/20260210/jishenhougailuosisaizujian（hanzuoyou）_1770686267784.png | U10: =VLOOKUP(N10,'散件（更新）'!B:G,6,FALSE) -> SP;CL2428C-01;机身后盖螺丝塞组件（含左右） | V10: =VLOOKUP(N10,'散件（更新）'!B:I,8,FALSE) -> 6932485020799
A11: 46169 | B11: FW770100DE | C11: =VLOOKUP(B11,'大货清单（不定期按GOMS更新）'!A:H,8,0) -> 109-24281001 | D11: =VLOOKUP(B11,'大货清单（不定期按GOMS更新）'!A:C,3,0) -> CL2428J-01 | E11: =VLOOKUP(B11,'大货清单（不定期按GOMS更新）'!A:H,4,0) -> DE | F11: =VLOOKUP(B11,'大货清单（不定期按GOMS更新）'!A:H,2,0) -> Floor One Station S9 Scientist | G11: =VLOOKUP(B11,'大货清单（不定期按GOMS更新）'!A:I,9,FALSE) -> 6971745581557 | H11: =VLOOKUP(B11,'大货清单（不定期按GOMS更新）'!A:H,7,0) -> Gray | I11: =VLOOKUP(B11,'大货清单（不定期按GOMS更新）'!A:F,6,FALSE) -> GTM | J11: =VLOOKUP(B11,'大货清单（不定期按GOMS更新）'!A:K,11,FALSE) -> 14.3 | K11: =VLOOKUP(B11,'大货清单（不定期按GOMS更新）'!A:N,12,FALSE) -> 785 | L11: =VLOOKUP(B11,'大货清单（不定期按GOMS更新）'!A:M,13,FALSE) -> 386 | M11: =VLOOKUP(B11,'大货清单（不定期按GOMS更新）'!A:N,14,FALSE) -> 367 | N11: 9FWRH510700 | O11: =IFERROR(VLOOKUP(N11,'散件迭代（不定期更新）'!C:J,8,FALSE),0) -> 0 | P11: =IFERROR(VLOOKUP(N11,'散件（更新）'!B:H,3,FALSE),0) | Q11: =VLOOKUP(N11,'散件（更新）'!B:H,2,FALSE) -> 114-24280320 | R11: =VLOOKUP(N11,'散件（更新）'!B:H,7,FALSE) -> Lower Decorative Cover | S11: =VLOOKUP(N11,'散件（更新）'!B:E,4,FALSE) -> https://tineco-yxzt.oss-accelerate.aliyuncs.com/20260210/jishenxiazhuangshigai_1770686308294.png | U11: =VLOOKUP(N11,'散件（更新）'!B:G,6,FALSE) -> SP;CL2428C-01;机身下装饰盖 | V11: =VLOOKUP(N11,'散件（更新）'!B:I,8,FALSE) -> 6932485020805
A12: 46169 | B12: FW770100DE | C12: =VLOOKUP(B12,'大货清单（不定期按GOMS更新）'!A:H,8,0) -> 109-24281001 | D12: =VLOOKUP(B12,'大货清单（不定期按GOMS更新）'!A:C,3,0) -> CL2428J-01 | E12: =VLOOKUP(B12,'大货清单（不定期按GOMS更新）'!A:H,4,0) -> DE | F12: =VLOOKUP(B12,'大货清单（不定期按GOMS更新）'!A:H,2,0) -> Floor One Station S9 Scientist | G12: =VLOOKUP(B12,'大货清单（不定期按GOMS更新）'!A:I,9,FALSE) -> 6971745581557 | H12: =VLOOKUP(B12,'大货清单（不定期按GOMS更新）'!A:H,7,0) -> Gray | I12: =VLOOKUP(B12,'大货清单（不定期按GOMS更新）'!A:F,6,FALSE) -> GTM | J12: =VLOOKUP(B12,'大货清单（不定期按GOMS更新）'!A:K,11,FALSE) -> 14.3 | K12: =VLOOKUP(B12,'大货清单（不定期按GOMS更新）'!A:N,12,FALSE) -> 785 | L12: =VLOOKUP(B12,'大货清单（不定期按GOMS更新）'!A:M,13,FALSE) -> 386 | M12: =VLOOKUP(B12,'大货清单（不定期按GOMS更新）'!A:N,14,FALSE) -> 367 | N12: 9FWRH510800 | O12: =IFERROR(VLOOKUP(N12,'散件迭代（不定期更新）'!C:J,8,FALSE),0) -> 0 | P12: =IFERROR(VLOOKUP(N12,'散件（更新）'!B:H,3,FALSE),0) | Q12: =VLOOKUP(N12,'散件（更新）'!B:H,2,FALSE) -> 114-24280321 | R12: =VLOOKUP(N12,'散件（更新）'!B:H,7,FALSE) -> Upper Decorative Cover | S12: =VLOOKUP(N12,'散件（更新）'!B:E,4,FALSE) -> https://tineco-yxzt.oss-accelerate.aliyuncs.com/20260210/jishenshangzhuangshigaibaojiaozujian_1770686364505.png | U12: =VLOOKUP(N12,'散件（更新）'!B:G,6,FALSE) -> SP;CL2428C-01;机身上装饰盖包胶组件 | V12: =VLOOKUP(N12,'散件（更新）'!B:I,8,FALSE) -> 6932485020812
A13: 46169 | B13: FW770100DE | C13: =VLOOKUP(B13,'大货清单（不定期按GOMS更新）'!A:H,8,0) -> 109-24281001 | D13: =VLOOKUP(B13,'大货清单（不定期按GOMS更新）'!A:C,3,0) -> CL2428J-01 | E13: =VLOOKUP(B13,'大货清单（不定期按GOMS更新）'!A:H,4,0) -> DE | F13: =VLOOKUP(B13,'大货清单（不定期按GOMS更新）'!A:H,2,0) -> Floor One Station S9 Scientist | G13: =VLOOKUP(B13,'大货清单（不定期按GOMS更新）'!A:I,9,FALSE) -> 6971745581557 | H13: =VLOOKUP(B13,'大货清单（不定期按GOMS更新）'!A:H,7,0) -> Gray | I13: =VLOOKUP(B13,'大货清单（不定期按GOMS更新）'!A:F,6,FALSE) -> GTM | J13: =VLOOKUP(B13,'大货清单（不定期按GOMS更新）'!A:K,11,FALSE) -> 14.3 | K13: =VLOOKUP(B13,'大货清单（不定期按GOMS更新）'!A:N,12,FALSE) -> 785 | L13: =VLOOKUP(B13,'大货清单（不定期按GOMS更新）'!A:M,13,FALSE) -> 386 | M13: =VLOOKUP(B13,'大货清单（不定期按GOMS更新）'!A:N,14,FALSE) -> 367 | N13: 9FWRH510900 | O13: =IFERROR(VLOOKUP(N13,'散件迭代（不定期更新）'!C:J,8,FALSE),0) -> 0 | P13: =IFERROR(VLOOKUP(N13,'散件（更新）'!B:H,3,FALSE),0) | Q13: =VLOOKUP(N13,'散件（更新）'!B:H,2,FALSE) -> 114-24280324 | R13: =VLOOKUP(N13,'散件（更新）'!B:H,7,FALSE) -> Brush Roller Motor Cover | S13: =VLOOKUP(N13,'散件（更新）'!B:E,4,FALSE) -> https://tineco-yxzt.oss-accelerate.aliyuncs.com/20260210/youshuadianjishoubinggaiban_1770686488756.png | U13: =VLOOKUP(N13,'散件（更新）'!B:G,6,FALSE) -> SP;CL2428C-01;有刷电机手柄盖板组件 | V13: =VLOOKUP(N13,'散件（更新）'!B:I,8,FALSE) -> 6932485020843
A14: 46169 | B14: FW770100DE | C14: =VLOOKUP(B14,'大货清单（不定期按GOMS更新）'!A:H,8,0) -> 109-24281001 | D14: =VLOOKUP(B14,'大货清单（不定期按GOMS更新）'!A:C,3,0) -> CL2428J-01 | E14: =VLOOKUP(B14,'大货清单（不定期按GOMS更新）'!A:H,4,0) -> DE | F14: =VLOOKUP(B14,'大货清单（不定期按GOMS更新）'!A:H,2,0) -> Floor One Station S9 Scientist | G14: =VLOOKUP(B14,'大货清单（不定期按GOMS更新）'!A:I,9,FALSE) -> 6971745581557 | H14: =VLOOKUP(B14,'大货清单（不定期按GOMS更新）'!A:H,7,0) -> Gray | I14: =VLOOKUP(B14,'大货清单（不定期按GOMS更新）'!A:F,6,FALSE) -> GTM | J14: =VLOOKUP(B14,'大货清单（不定期按GOMS更新）'!A:K,11,FALSE) -> 14.3 | K14: =VLOOKUP(B14,'大货清单（不定期按GOMS更新）'!A:N,12,FALSE) -> 785 | L14: =VLOOKUP(B14,'大货清单（不定期按GOMS更新）'!A:M,13,FALSE) -> 386 | M14: =VLOOKUP(B14,'大货清单（不定期按GOMS更新）'!A:N,14,FALSE) -> 367 | N14: 9FWRH511000 | O14: =IFERROR(VLOOKUP(N14,'散件迭代（不定期更新）'!C:J,8,FALSE),0) -> 0 | P14: =IFERROR(VLOOKUP(N14,'散件（更新）'!B:H,3,FALSE),0) | Q14: =VLOOKUP(N14,'散件（更新）'!B:H,2,FALSE) -> 114-24280325 | R14: =VLOOKUP(N14,'散件（更新）'!B:H,7,FALSE) -> Bracket | S14: =VLOOKUP(N14,'散件（更新）'!B:E,4,FALSE) -> https://tineco-yxzt.oss-accelerate.aliyuncs.com/20260210/fuhezhijie_1770686543026.png | U14: =VLOOKUP(N14,'散件（更新）'!B:G,6,FALSE) -> SP;CL2428C-01;复合支架 | V14: =VLOOKUP(N14,'散件（更新）'!B:I,8,FALSE) -> 6932485020850
A15: 46169 | B15: FW770100DE | C15: =VLOOKUP(B15,'大货清单（不定期按GOMS更新）'!A:H,8,0) -> 109-24281001 | D15: =VLOOKUP(B15,'大货清单（不定期按GOMS更新）'!A:C,3,0) -> CL2428J-01 | E15: =VLOOKUP(B15,'大货清单（不定期按GOMS更新）'!A:H,4,0) -> DE | F15: =VLOOKUP(B15,'大货清单（不定期按GOMS更新）'!A:H,2,0) -> Floor One Station S9 Scientist | G15: =VLOOKUP(B15,'大货清单（不定期按GOMS更新）'!A:I,9,FALSE) -> 6971745581557 | H15: =VLOOKUP(B15,'大货清单（不定期按GOMS更新）'!A:H,7,0) -> Gray | I15: =VLOOKUP(B15,'大货清单（不定期按GOMS更新）'!A:F,6,FALSE) -> GTM | J15: =VLOOKUP(B15,'大货清单（不定期按GOMS更新）'!A:K,11,FALSE) -> 14.3 | K15: =VLOOKUP(B15,'大货清单（不定期按GOMS更新）'!A:N,12,FALSE) -> 785 | L15: =VLOOKUP(B15,'大货清单（不定期按GOMS更新）'!A:M,13,FALSE) -> 386 | M15: =VLOOKUP(B15,'大货清单（不定期按GOMS更新）'!A:N,14,FALSE) -> 367 | N15: 9FWRH511200 | O15: =IFERROR(VLOOKUP(N15,'散件迭代（不定期更新）'!C:J,8,FALSE),0) -> 0 | P15: =IFERROR(VLOOKUP(N15,'散件（更新）'!B:H,3,FALSE),0) | Q15: =VLOOKUP(N15,'散件（更新）'!B:H,2,FALSE) -> 114-24280329 | R15: =VLOOKUP(N15,'散件（更新）'!B:H,7,FALSE) -> Light Guide Plate Assembly | S15: =VLOOKUP(N15,'散件（更新）'!B:E,4,FALSE) -> https://tineco-yxzt.oss-accelerate.aliyuncs.com/20260210/daoguangbanzujian（daoguangban＋waiqiao）_1770687154481.png | U15: =VLOOKUP(N15,'散件（更新）'!B:G,6,FALSE) -> SP;CL2428C-01;导光板组件（导光板＋外壳） | V15: =VLOOKUP(N15,'散件（更新）'!B:I,8,FALSE) -> 6932485020898
A16: 46169 | B16: FW770100DE | C16: =VLOOKUP(B16,'大货清单（不定期按GOMS更新）'!A:H,8,0) -> 109-24281001 | D16: =VLOOKUP(B16,'大货清单（不定期按GOMS更新）'!A:C,3,0) -> CL2428J-01 | E16: =VLOOKUP(B16,'大货清单（不定期按GOMS更新）'!A:H,4,0) -> DE | F16: =VLOOKUP(B16,'大货清单（不定期按GOMS更新）'!A:H,2,0) -> Floor One Station S9 Scientist | G16: =VLOOKUP(B16,'大货清单（不定期按GOMS更新）'!A:I,9,FALSE) -> 6971745581557 | H16: =VLOOKUP(B16,'大货清单（不定期按GOMS更新）'!A:H,7,0) -> Gray | I16: =VLOOKUP(B16,'大货清单（不定期按GOMS更新）'!A:F,6,FALSE) -> GTM | J16: =VLOOKUP(B16,'大货清单（不定期按GOMS更新）'!A:K,11,FALSE) -> 14.3 | K16: =VLOOKUP(B16,'大货清单（不定期按GOMS更新）'!A:N,12,FALSE) -> 785 | L16: =VLOOKUP(B16,'大货清单（不定期按GOMS更新）'!A:M,13,FALSE) -> 386 | M16: =VLOOKUP(B16,'大货清单（不定期按GOMS更新）'!A:N,14,FALSE) -> 367 | N16: 9FWRH541100 | O16: =IFERROR(VLOOKUP(N16,'散件迭代（不定期更新）'!C:J,8,FALSE),0) -> 0 | P16: =IFERROR(VLOOKUP(N16,'散件（更新）'!B:H,3,FALSE),0) | Q16: =VLOOKUP(N16,'散件（更新）'!B:H,2,FALSE) -> 114-25390617 | R16: =VLOOKUP(N16,'散件（更新）'!B:H,7,FALSE) -> Hot Water Inlet Valve | S16: =VLOOKUP(N16,'散件（更新）'!B:E,4,FALSE) -> https://tineco-yxzt.oss-accelerate.aliyuncs.com/20260206/reshuishangshuifa_1770359911226.JPG | U16: =VLOOKUP(N16,'散件（更新）'!B:G,6,FALSE) -> SP;CL2539F-01;热水上水阀 | V16: =VLOOKUP(N16,'散件（更新）'!B:I,8,FALSE) -> 6932485021550
A17: 46169 | B17: FW770100DE | C17: =VLOOKUP(B17,'大货清单（不定期按GOMS更新）'!A:H,8,0) -> 109-24281001 | D17: =VLOOKUP(B17,'大货清单（不定期按GOMS更新）'!A:C,3,0) -> CL2428J-01 | E17: =VLOOKUP(B17,'大货清单（不定期按GOMS更新）'!A:H,4,0) -> DE | F17: =VLOOKUP(B17,'大货清单（不定期按GOMS更新）'!A:H,2,0) -> Floor One Station S9 Scientist | G17: =VLOOKUP(B17,'大货清单（不定期按GOMS更新）'!A:I,9,FALSE) -> 6971745581557 | H17: =VLOOKUP(B17,'大货清单（不定期按GOMS更新）'!A:H,7,0) -> Gray | I17: =VLOOKUP(B17,'大货清单（不定期按GOMS更新）'!A:F,6,FALSE) -> GTM | J17: =VLOOKUP(B17,'大货清单（不定期按GOMS更新）'!A:K,11,FALSE) -> 14.3 | K17: =VLOOKUP(B17,'大货清单（不定期按GOMS更新）'!A:N,12,FALSE) -> 785 | L17: =VLOOKUP(B17,'大货清单（不定期按GOMS更新）'!A:M,13,FALSE) -> 386 | M17: =VLOOKUP(B17,'大货清单（不定期按GOMS更新）'!A:N,14,FALSE) -> 367 | N17: 9FWRH541200 | O17: =IFERROR(VLOOKUP(N17,'散件迭代（不定期更新）'!C:J,8,FALSE),0) -> 0 | P17: =IFERROR(VLOOKUP(N17,'散件（更新）'!B:H,3,FALSE),0) | Q17: =VLOOKUP(N17,'散件（更新）'!B:H,2,FALSE) -> 114-25390618 | R17: =VLOOKUP(N17,'散件（更新）'!B:H,7,FALSE) -> Charging base Foot Pad (1 pc) | S17: =VLOOKUP(N17,'散件（更新）'!B:E,4,FALSE) -> https://tineco-yxzt.oss-accelerate.aliyuncs.com/20260206/IMG_2720_1770359962427.JPG | U17: =VLOOKUP(N17,'散件（更新）'!B:G,6,FALSE) -> SP;CL2539F-01;托盘脚垫（1个） | V17: =VLOOKUP(N17,'散件（更新）'!B:I,8,FALSE) -> 6932485021567
... A20: 46169 | B20: FW770100DE | C20: =VLOOKUP(B20,'大货清单（不定期按GOMS更新）'!A:H,8,0) -> 109-24281001 | D20: =VLOOKUP(B20,'大货清单（不定期按GOMS更新）'!A:C,3,0) -> CL2428J-01 | E20: =VLOOKUP(B20,'大货清单（不定期按GOMS更新）'!A:H,4,0) -> DE | F20: =VLOOKUP(B20,'大货清单（不定期按GOMS更新）'!A:H,2,0) -> Floor One Station S9 Scientist | G20: =VLOOKUP(B20,'大货清单（不定期按GOMS更新）'!A:I,9,FALSE) -> 6971745581557 | H20: =VLOOKUP(B20,'大货清单（不定期按GOMS更新）'!A:H,7,0) -> Gray | I20: =VLOOKUP(B20,'大货清单（不定期按GOMS更新）'!A:F,6,FALSE) -> GTM | J20: =VLOOKUP(B20,'大货清单（不定期按GOMS更新）'!A:K,11,FALSE) -> 14.3 | K20: =VLOOKUP(B20,'大货清单（不定期按GOMS更新）'!A:N,12,FALSE) -> 785 | L20: =VLOOKUP(B20,'大货清单（不定期按GOMS更新）'!A:M,13,FALSE) -> 386 | M20: =VLOOKUP(B20,'大货清单（不定期按GOMS更新）'!A:N,14,FALSE) -> 367 | N20: 9FWRH641100 | O20: =IFERROR(VLOOKUP(N20,'散件迭代（不定期更新）'!C:J,8,FALSE),0) -> 0 | P20: =IFERROR(VLOOKUP(N20,'散件（更新）'!B:H,3,FALSE),0) | Q20: =VLOOKUP(N20,'散件（更新）'!B:H,2,FALSE) -> 114-24360424 | R20: =VLOOKUP(N20,'散件（更新）'!B:H,7,FALSE) -> Floor Brush Base Bracket Assembly | S20: =VLOOKUP(N20,'散件（更新）'!B:E,4,FALSE) -> https://tineco-yxzt.oss-accelerate.aliyuncs.com/20251223/114-24360424dishuadizuozhijiazujian_1766487217167.jpg | U20: =VLOOKUP(N20,'散件（更新）'!B:G,6,FALSE) -> SP;CL2436D-01;地刷底座支架组件 | V20: =VLOOKUP(N20,'散件（更新）'!B:I,8,FALSE) -> 6932485018765
A21: 46169 | B21: FW770100DE | C21: =VLOOKUP(B21,'大货清单（不定期按GOMS更新）'!A:H,8,0) -> 109-24281001 | D21: =VLOOKUP(B21,'大货清单（不定期按GOMS更新）'!A:C,3,0) -> CL2428J-01 | E21: =VLOOKUP(B21,'大货清单（不定期按GOMS更新）'!A:H,4,0) -> DE | F21: =VLOOKUP(B21,'大货清单（不定期按GOMS更新）'!A:H,2,0) -> Floor One Station S9 Scientist | G21: =VLOOKUP(B21,'大货清单（不定期按GOMS更新）'!A:I,9,FALSE) -> 6971745581557 | H21: =VLOOKUP(B21,'大货清单（不定期按GOMS更新）'!A:H,7,0) -> Gray | I21: =VLOOKUP(B21,'大货清单（不定期按GOMS更新）'!A:F,6,FALSE) -> GTM | J21: =VLOOKUP(B21,'大货清单（不定期按GOMS更新）'!A:K,11,FALSE) -> 14.3 | K21: =VLOOKUP(B21,'大货清单（不定期按GOMS更新）'!A:N,12,FALSE) -> 785 | L21: =VLOOKUP(B21,'大货清单（不定期按GOMS更新）'!A:M,13,FALSE) -> 386 | M21: =VLOOKUP(B21,'大货清单（不定期按GOMS更新）'!A:N,14,FALSE) -> 367 | N21: 9FWRI510000 | O21: =IFERROR(VLOOKUP(N21,'散件迭代（不定期更新）'!C:J,8,FALSE),0) -> 0 | P21: =IFERROR(VLOOKUP(N21,'散件（更新）'!B:H,3,FALSE),0) | Q21: =VLOOKUP(N21,'散件（更新）'!B:H,2,FALSE) -> 114-24280328 | R21: =VLOOKUP(N21,'散件（更新）'!B:H,7,FALSE) -> DWT Signal Detection Sensor | S21: =VLOOKUP(N21,'散件（更新）'!B:E,4,FALSE) -> https://tineco-yxzt.oss-accelerate.aliyuncs.com/20260210/wushuitongshuimanjiancedaoxian_1770687075742.png | T21: for brush | U21: =VLOOKUP(N21,'散件（更新）'!B:G,6,FALSE) -> SP;CL2428C-01;污水桶水满检测导线 | V21: =VLOOKUP(N21,'散件（更新）'!B:I,8,FALSE) -> 6932485020881
A22: 46169 | B22: FW770100DE | C22: =VLOOKUP(B22,'大货清单（不定期按GOMS更新）'!A:H,8,0) -> 109-24281001 | D22: =VLOOKUP(B22,'大货清单（不定期按GOMS更新）'!A:C,3,0) -> CL2428J-01 | E22: =VLOOKUP(B22,'大货清单（不定期按GOMS更新）'!A:H,4,0) -> DE | F22: =VLOOKUP(B22,'大货清单（不定期按GOMS更新）'!A:H,2,0) -> Floor One Station S9 Scientist | G22: =VLOOKUP(B22,'大货清单（不定期按GOMS更新）'!A:I,9,FALSE) -> 6971745581557 | H22: =VLOOKUP(B22,'大货清单（不定期按GOMS更新）'!A:H,7,0) -> Gray | I22: =VLOOKUP(B22,'大货清单（不定期按GOMS更新）'!A:F,6,FALSE) -> GTM | J22: =VLOOKUP(B22,'大货清单（不定期按GOMS更新）'!A:K,11,FALSE) -> 14.3 | K22: =VLOOKUP(B22,'大货清单（不定期按GOMS更新）'!A:N,12,FALSE) -> 785 | L22: =VLOOKUP(B22,'大货清单（不定期按GOMS更新）'!A:M,13,FALSE) -> 386 | M22: =VLOOKUP(B22,'大货清单（不定期按GOMS更新）'!A:N,14,FALSE) -> 367 | N22: 9FWRI540100 | O22: =IFERROR(VLOOKUP(N22,'散件迭代（不定期更新）'!C:J,8,FALSE),0) -> 0 | P22: =IFERROR(VLOOKUP(N22,'散件（更新）'!B:H,3,FALSE),0) | Q22: =VLOOKUP(N22,'散件（更新）'!B:H,2,FALSE) -> 114-25390613 | R22: =VLOOKUP(N22,'散件（更新）'!B:H,7,FALSE) -> Brush Roller Assembly Charging Connection Wire | S22: =VLOOKUP(N22,'散件（更新）'!B:E,4,FALSE) -> https://tineco-yxzt.oss-accelerate.aliyuncs.com/20260206/dishuachongdianduijiedaoxianzujian_1770359543679.JPG | U22: =VLOOKUP(N22,'散件（更新）'!B:G,6,FALSE) -> SP;CL2539F-01;地刷充电对接导线组件 | V22: =VLOOKUP(N22,'散件（更新）'!B:I,8,FALSE) -> 6932485021512
A23: 46169 | B23: FW770100DE | C23: =VLOOKUP(B23,'大货清单（不定期按GOMS更新）'!A:H,8,0) -> 109-24281001 | D23: =VLOOKUP(B23,'大货清单（不定期按GOMS更新）'!A:C,3,0) -> CL2428J-01 | E23: =VLOOKUP(B23,'大货清单（不定期按GOMS更新）'!A:H,4,0) -> DE | F23: =VLOOKUP(B23,'大货清单（不定期按GOMS更新）'!A:H,2,0) -> Floor One Station S9 Scientist | G23: =VLOOKUP(B23,'大货清单（不定期按GOMS更新）'!A:I,9,FALSE) -> 6971745581557 | H23: =VLOOKUP(B23,'大货清单（不定期按GOMS更新）'!A:H,7,0) -> Gray | I23: =VLOOKUP(B23,'大货清单（不定期按GOMS更新）'!A:F,6,FALSE) -> GTM | J23: =VLOOKUP(B23,'大货清单（不定期按GOMS更新）'!A:K,11,FALSE) -> 14.3 | K23: =VLOOKUP(B23,'大货清单（不定期按GOMS更新）'!A:N,12,FALSE) -> 785 | L23: =VLOOKUP(B23,'大货清单（不定期按GOMS更新）'!A:M,13,FALSE) -> 386 | M23: =VLOOKUP(B23,'大货清单（不定期按GOMS更新）'!A:N,14,FALSE) -> 367 | N23: 9FWRI540200 | O23: =IFERROR(VLOOKUP(N23,'散件迭代（不定期更新）'!C:J,8,FALSE),0) -> 0 | P23: =IFERROR(VLOOKUP(N23,'散件（更新）'!B:H,3,FALSE),0) | Q23: =VLOOKUP(N23,'散件（更新）'!B:H,2,FALSE) -> 114-25390616 | R23: =VLOOKUP(N23,'散件（更新）'!B:H,7,FALSE) -> Charging Connection Wire Assembly Of Charging Base | S23: =VLOOKUP(N23,'散件（更新）'!B:E,4,FALSE) -> https://tineco-yxzt.oss-accelerate.aliyuncs.com/20260206/IMG_2709_1770359810017.JPG | U23: =VLOOKUP(N23,'散件（更新）'!B:G,6,FALSE) -> SP;CL2539F-01;充电座组件+充电通讯导线 | V23: =VLOOKUP(N23,'散件（更新）'!B:I,8,FALSE) -> 6932485021543
A24: 46169 | B24: FW770100DE | C24: =VLOOKUP(B24,'大货清单（不定期按GOMS更新）'!A:H,8,0) -> 109-24281001 | D24: =VLOOKUP(B24,'大货清单（不定期按GOMS更新）'!A:C,3,0) -> CL2428J-01 | E24: =VLOOKUP(B24,'大货清单（不定期按GOMS更新）'!A:H,4,0) -> DE | F24: =VLOOKUP(B24,'大货清单（不定期按GOMS更新）'!A:H,2,0) -> Floor One Station S9 Scientist | G24: =VLOOKUP(B24,'大货清单（不定期按GOMS更新）'!A:I,9,FALSE) -> 6971745581557 | H24: =VLOOKUP(B24,'大货清单（不定期按GOMS更新）'!A:H,7,0) -> Gray | I24: =VLOOKUP(B24,'大货清单（不定期按GOMS更新）'!A:F,6,FALSE) -> GTM | J24: =VLOOKUP(B24,'大货清单（不定期按GOMS更新）'!A:K,11,FALSE) -> 14.3 | K24: =VLOOKUP(B24,'大货清单（不定期按GOMS更新）'!A:N,12,FALSE) -> 785 | L24: =VLOOKUP(B24,'大货清单（不定期按GOMS更新）'!A:M,13,FALSE) -> 386 | M24: =VLOOKUP(B24,'大货清单（不定期按GOMS更新）'!A:N,14,FALSE) -> 367 | N24: 9FWRI540300 | O24: =IFERROR(VLOOKUP(N24,'散件迭代（不定期更新）'!C:J,8,FALSE),0) -> 0 | P24: =IFERROR(VLOOKUP(N24,'散件（更新）'!B:H,3,FALSE),0) | Q24: =VLOOKUP(N24,'散件（更新）'!B:H,2,FALSE) -> 114-25390623 | R24: =VLOOKUP(N24,'散件（更新）'!B:H,7,FALSE) -> Power Cord | S24: =VLOOKUP(N24,'散件（更新）'!B:E,4,FALSE) -> https://tineco-yxzt.oss-accelerate.aliyuncs.com/20260206/wannengoubansanchadianyuanxian_1770360231084.JPG | U24: =VLOOKUP(N24,'散件（更新）'!B:G,6,FALSE) -> SP;CL2539F-01;万能欧版三插电源线 | V24: =VLOOKUP(N24,'散件（更新）'!B:I,8,FALSE) -> 6932485021611
A25: 46169 | B25: FW770100DE | C25: =VLOOKUP(B25,'大货清单（不定期按GOMS更新）'!A:H,8,0) -> 109-24281001 | D25: =VLOOKUP(B25,'大货清单（不定期按GOMS更新）'!A:C,3,0) -> CL2428J-01 | E25: =VLOOKUP(B25,'大货清单（不定期按GOMS更新）'!A:H,4,0) -> DE | F25: =VLOOKUP(B25,'大货清单（不定期按GOMS更新）'!A:H,2,0) -> Floor One Station S9 Scientist | G25: =VLOOKUP(B25,'大货清单（不定期按GOMS更新）'!A:I,9,FALSE) -> 6971745581557 | H25: =VLOOKUP(B25,'大货清单（不定期按GOMS更新）'!A:H,7,0) -> Gray | I25: =VLOOKUP(B25,'大货清单（不定期按GOMS更新）'!A:F,6,FALSE) -> GTM | J25: =VLOOKUP(B25,'大货清单（不定期按GOMS更新）'!A:K,11,FALSE) -> 14.3 | K25: =VLOOKUP(B25,'大货清单（不定期按GOMS更新）'!A:N,12,FALSE) -> 785 | L25: =VLOOKUP(B25,'大货清单（不定期按GOMS更新）'!A:M,13,FALSE) -> 386 | M25: =VLOOKUP(B25,'大货清单（不定期按GOMS更新）'!A:N,14,FALSE) -> 367 | N25: 9FWRK360000 | O25: =IFERROR(VLOOKUP(N25,'散件迭代（不定期更新）'!C:J,8,FALSE),0) -> 0 | P25: =IFERROR(VLOOKUP(N25,'散件（更新）'!B:H,3,FALSE),0) | Q25: =VLOOKUP(N25,'散件（更新）'!B:H,2,FALSE) -> 114-24570002 | R25: =VLOOKUP(N25,'散件（更新）'!B:H,7,FALSE) -> Switch | S25: =VLOOKUP(N25,'散件（更新）'!B:E,4,FALSE) -> https://tineco-yxzt.oss-accelerate.aliyuncs.com/20250114/32131_1736819450296.jpg | U25: =VLOOKUP(N25,'散件（更新）'!B:G,6,FALSE) -> 微动开关 | V25: =VLOOKUP(N25,'散件（更新）'!B:I,8,FALSE) -> 6932485002955
A26: 46169 | B26: FW770100DE | C26: =VLOOKUP(B26,'大货清单（不定期按GOMS更新）'!A:H,8,0) -> 109-24281001 | D26: =VLOOKUP(B26,'大货清单（不定期按GOMS更新）'!A:C,3,0) -> CL2428J-01 | E26: =VLOOKUP(B26,'大货清单（不定期按GOMS更新）'!A:H,4,0) -> DE | F26: =VLOOKUP(B26,'大货清单（不定期按GOMS更新）'!A:H,2,0) -> Floor One Station S9 Scientist | G26: =VLOOKUP(B26,'大货清单（不定期按GOMS更新）'!A:I,9,FALSE) -> 6971745581557 | H26: =VLOOKUP(B26,'大货清单（不定期按GOMS更新）'!A:H,7,0) -> Gray | I26: =VLOOKUP(B26,'大货清单（不定期按GOMS更新）'!A:F,6,FALSE) -> GTM | J26: =VLOOKUP(B26,'大货清单（不定期按GOMS更新）'!A:K,11,FALSE) -> 14.3 | K26: =VLOOKUP(B26,'大货清单（不定期按GOMS更新）'!A:N,12,FALSE) -> 785 | L26: =VLOOKUP(B26,'大货清单（不定期按GOMS更新）'!A:M,13,FALSE) -> 386 | M26: =VLOOKUP(B26,'大货清单（不定期按GOMS更新）'!A:N,14,FALSE) -> 367 | N26: 9FWRK4A0000 | O26: =IFERROR(VLOOKUP(N26,'散件迭代（不定期更新）'!C:J,8,FALSE),0) -> 0 | P26: =IFERROR(VLOOKUP(N26,'散件（更新）'!B:H,3,FALSE),0) -> 0 | Q26: =VLOOKUP(N26,'散件（更新）'!B:H,2,FALSE) -> 114-25350302 | R26: =VLOOKUP(N26,'散件（更新）'!B:H,7,FALSE) -> Micro Switch ＋Wire | S26: =VLOOKUP(N26,'散件（更新）'!B:E,4,FALSE) -> https://tineco-yxzt.oss-accelerate.aliyuncs.com/20250912/0180e578-009f-4e2b-b7eb-c52b6b19abaa_1757659464697.png | U26: =VLOOKUP(N26,'散件（更新）'!B:G,6,FALSE) -> SP;CL2535C-01;微动开关+导线 | V26: =VLOOKUP(N26,'散件（更新）'!B:I,8,FALSE) -> 6932485013548
A27: 46169 | B27: FW770100DE | C27: =VLOOKUP(B27,'大货清单（不定期按GOMS更新）'!A:H,8,0) -> 109-24281001 | D27: =VLOOKUP(B27,'大货清单（不定期按GOMS更新）'!A:C,3,0) -> CL2428J-01 | E27: =VLOOKUP(B27,'大货清单（不定期按GOMS更新）'!A:H,4,0) -> DE | F27: =VLOOKUP(B27,'大货清单（不定期按GOMS更新）'!A:H,2,0) -> Floor One Station S9 Scientist | G27: =VLOOKUP(B27,'大货清单（不定期按GOMS更新）'!A:I,9,FALSE) -> 6971745581557 | H27: =VLOOKUP(B27,'大货清单（不定期按GOMS更新）'!A:H,7,0) -> Gray | I27: =VLOOKUP(B27,'大货清单（不定期按GOMS更新）'!A:F,6,FALSE) -> GTM | J27: =VLOOKUP(B27,'大货清单（不定期按GOMS更新）'!A:K,11,FALSE) -> 14.3 | K27: =VLOOKUP(B27,'大货清单（不定期按GOMS更新）'!A:N,12,FALSE) -> 785 | L27: =VLOOKUP(B27,'大货清单（不定期按GOMS更新）'!A:M,13,FALSE) -> 386 | M27: =VLOOKUP(B27,'大货清单（不定期按GOMS更新）'!A:N,14,FALSE) -> 367 | N27: 9FWRM510000 | O27: =IFERROR(VLOOKUP(N27,'散件迭代（不定期更新）'!C:J,8,FALSE),0) -> 0 | P27: =IFERROR(VLOOKUP(N27,'散件（更新）'!B:H,3,FALSE),0) | Q27: =VLOOKUP(N27,'散件（更新）'!B:H,2,FALSE) -> 114-24280301 | R27: =VLOOKUP(N27,'散件（更新）'!B:H,7,FALSE) -> Servo Motor Assembly | S27: =VLOOKUP(N27,'散件（更新）'!B:E,4,FALSE) -> https://tineco-yxzt.oss-accelerate.aliyuncs.com/20260210/duojizujian_1770685213285.png | U27: =VLOOKUP(N27,'散件（更新）'!B:G,6,FALSE) -> SP;CL2428C-01;舵机组件 | V27: =VLOOKUP(N27,'散件（更新）'!B:I,8,FALSE) -> 6932485020614
A28: 46169 | B28: FW770100DE | C28: =VLOOKUP(B28,'大货清单（不定期按GOMS更新）'!A:H,8,0) -> 109-24281001 | D28: =VLOOKUP(B28,'大货清单（不定期按GOMS更新）'!A:C,3,0) -> CL2428J-01 | E28: =VLOOKUP(B28,'大货清单（不定期按GOMS更新）'!A:H,4,0) -> DE | F28: =VLOOKUP(B28,'大货清单（不定期按GOMS更新）'!A:H,2,0) -> Floor One Station S9 Scientist | G28: =VLOOKUP(B28,'大货清单（不定期按GOMS更新）'!A:I,9,FALSE) -> 6971745581557 | H28: =VLOOKUP(B28,'大货清单（不定期按GOMS更新）'!A:H,7,0) -> Gray | I28: =VLOOKUP(B28,'大货清单（不定期按GOMS更新）'!A:F,6,FALSE) -> GTM | J28: =VLOOKUP(B28,'大货清单（不定期按GOMS更新）'!A:K,11,FALSE) -> 14.3 | K28: =VLOOKUP(B28,'大货清单（不定期按GOMS更新）'!A:N,12,FALSE) -> 785 | L28: =VLOOKUP(B28,'大货清单（不定期按GOMS更新）'!A:M,13,FALSE) -> 386 | M28: =VLOOKUP(B28,'大货清单（不定期按GOMS更新）'!A:N,14,FALSE) -> 367 | N28: 9FWRM540000 | O28: =IFERROR(VLOOKUP(N28,'散件迭代（不定期更新）'!C:J,8,FALSE),0) -> 0 | P28: =IFERROR(VLOOKUP(N28,'散件（更新）'!B:H,3,FALSE),0) | Q28: =VLOOKUP(N28,'散件（更新）'!B:H,2,FALSE) -> 114-25390619 | R28: =VLOOKUP(N28,'散件（更新）'!B:H,7,FALSE) -> Charging base Fan Assembly | S28: =VLOOKUP(N28,'散件（更新）'!B:E,4,FALSE) -> https://tineco-yxzt.oss-accelerate.aliyuncs.com/20260206/tuopanfengjizujian_1770360002589.JPG | U28: =VLOOKUP(N28,'散件（更新）'!B:G,6,FALSE) -> SP;CL2539F-01;托盘风机组件 | V28: =VLOOKUP(N28,'散件（更新）'!B:I,8,FALSE) -> 6932485021574
A29: 46169 | B29: FW770100DE | C29: =VLOOKUP(B29,'大货清单（不定期按GOMS更新）'!A:H,8,0) -> 109-24281001 | D29: =VLOOKUP(B29,'大货清单（不定期按GOMS更新）'!A:C,3,0) -> CL2428J-01 | E29: =VLOOKUP(B29,'大货清单（不定期按GOMS更新）'!A:H,4,0) -> DE | F29: =VLOOKUP(B29,'大货清单（不定期按GOMS更新）'!A:H,2,0) -> Floor One Station S9 Scientist | G29: =VLOOKUP(B29,'大货清单（不定期按GOMS更新）'!A:I,9,FALSE) -> 6971745581557 | H29: =VLOOKUP(B29,'大货清单（不定期按GOMS更新）'!A:H,7,0) -> Gray | I29: =VLOOKUP(B29,'大货清单（不定期按GOMS更新）'!A:F,6,FALSE) -> GTM | J29: =VLOOKUP(B29,'大货清单（不定期按GOMS更新）'!A:K,11,FALSE) -> 14.3 | K29: =VLOOKUP(B29,'大货清单（不定期按GOMS更新）'!A:N,12,FALSE) -> 785 | L29: =VLOOKUP(B29,'大货清单（不定期按GOMS更新）'!A:M,13,FALSE) -> 386 | M29: =VLOOKUP(B29,'大货清单（不定期按GOMS更新）'!A:N,14,FALSE) -> 367 | N29: 9FWRM6300VN | O29: =IFERROR(VLOOKUP(N29,'散件迭代（不定期更新）'!C:J,8,FALSE),0) -> 0 | P29: =IFERROR(VLOOKUP(N29,'散件（更新）'!B:H,3,FALSE),0) -> 0 | Q29: =VLOOKUP(N29,'散件（更新）'!B:H,2,FALSE) -> 114-25620002 | R29: =VLOOKUP(N29,'散件（更新）'!B:H,7,FALSE) -> Main Motor | S29: =VLOOKUP(N29,'散件（更新）'!B:E,4,FALSE) -> 0 | U29: =VLOOKUP(N29,'散件（更新）'!B:G,6,FALSE) -> SP;CL2562-01;主电机 | V29: =VLOOKUP(N29,'散件（更新）'!B:I,8,FALSE) -> 6932485016242
A30: 46169 | B30: FW770100DE | C30: =VLOOKUP(B30,'大货清单（不定期按GOMS更新）'!A:H,8,0) -> 109-24281001 | D30: =VLOOKUP(B30,'大货清单（不定期按GOMS更新）'!A:C,3,0) -> CL2428J-01 | E30: =VLOOKUP(B30,'大货清单（不定期按GOMS更新）'!A:H,4,0) -> DE | F30: =VLOOKUP(B30,'大货清单（不定期按GOMS更新）'!A:H,2,0) -> Floor One Station S9 Scientist | G30: =VLOOKUP(B30,'大货清单（不定期按GOMS更新）'!A:I,9,FALSE) -> 6971745581557 | H30: =VLOOKUP(B30,'大货清单（不定期按GOMS更新）'!A:H,7,0) -> Gray | I30: =VLOOKUP(B30,'大货清单（不定期按GOMS更新）'!A:F,6,FALSE) -> GTM | J30: =VLOOKUP(B30,'大货清单（不定期按GOMS更新）'!A:K,11,FALSE) -> 14.3 | K30: =VLOOKUP(B30,'大货清单（不定期按GOMS更新）'!A:N,12,FALSE) -> 785 | L30: =VLOOKUP(B30,'大货清单（不定期按GOMS更新）'!A:M,13,FALSE) -> 386 | M30: =VLOOKUP(B30,'大货清单（不定期按GOMS更新）'!A:N,14,FALSE) -> 367 | N30: 9FWRO540000 | O30: =IFERROR(VLOOKUP(N30,'散件迭代（不定期更新）'!C:J,8,FALSE),0) -> 0 | P30: =IFERROR(VLOOKUP(N30,'散件（更新）'!B:H,3,FALSE),0) | Q30: =VLOOKUP(N30,'散件（更新）'!B:H,2,FALSE) -> 114-25390622 | R30: =VLOOKUP(N30,'散件（更新）'!B:H,7,FALSE) -> Heating Tube | S30: =VLOOKUP(N30,'散件（更新）'!B:E,4,FALSE) -> https://tineco-yxzt.oss-accelerate.aliyuncs.com/20260206/jiareguan_1770360172000.JPG | U30: =VLOOKUP(N30,'散件（更新）'!B:G,6,FALSE) -> SP;CL2539F-01;加热管 | V30: =VLOOKUP(N30,'散件（更新）'!B:I,8,FALSE) -> 6932485021604
A31: 46169 | B31: FW770100DE | C31: =VLOOKUP(B31,'大货清单（不定期按GOMS更新）'!A:H,8,0) -> 109-24281001 | D31: =VLOOKUP(B31,'大货清单（不定期按GOMS更新）'!A:C,3,0) -> CL2428J-01 | E31: =VLOOKUP(B31,'大货清单（不定期按GOMS更新）'!A:H,4,0) -> DE | F31: =VLOOKUP(B31,'大货清单（不定期按GOMS更新）'!A:H,2,0) -> Floor One Station S9 Scientist | G31: =VLOOKUP(B31,'大货清单（不定期按GOMS更新）'!A:I,9,FALSE) -> 6971745581557 | H31: =VLOOKUP(B31,'大货清单（不定期按GOMS更新）'!A:H,7,0) -> Gray | I31: =VLOOKUP(B31,'大货清单（不定期按GOMS更新）'!A:F,6,FALSE) -> GTM | J31: =VLOOKUP(B31,'大货清单（不定期按GOMS更新）'!A:K,11,FALSE) -> 14.3 | K31: =VLOOKUP(B31,'大货清单（不定期按GOMS更新）'!A:N,12,FALSE) -> 785 | L31: =VLOOKUP(B31,'大货清单（不定期按GOMS更新）'!A:M,13,FALSE) -> 386 | M31: =VLOOKUP(B31,'大货清单（不定期按GOMS更新）'!A:N,14,FALSE) -> 367 | N31: 9FWRO540100 | O31: =IFERROR(VLOOKUP(N31,'散件迭代（不定期更新）'!C:J,8,FALSE),0) -> 0 | P31: =IFERROR(VLOOKUP(N31,'散件（更新）'!B:H,3,FALSE),0) | Q31: =VLOOKUP(N31,'散件（更新）'!B:H,2,FALSE) -> 114-25390639 | R31: =VLOOKUP(N31,'散件（更新）'!B:H,7,FALSE) -> Heating Wire Assembly | S31: =VLOOKUP(N31,'散件（更新）'!B:E,4,FALSE) -> https://tineco-yxzt.oss-accelerate.aliyuncs.com/20260206/faresizujian_1770361079643.JPG | U31: =VLOOKUP(N31,'散件（更新）'!B:G,6,FALSE) -> SP;CL2539F-01;发热丝组件 | V31: =VLOOKUP(N31,'散件（更新）'!B:I,8,FALSE) -> 6932485021765
A32: 46169 | B32: FW770100DE | C32: =VLOOKUP(B32,'大货清单（不定期按GOMS更新）'!A:H,8,0) -> 109-24281001 | D32: =VLOOKUP(B32,'大货清单（不定期按GOMS更新）'!A:C,3,0) -> CL2428J-01 | E32: =VLOOKUP(B32,'大货清单（不定期按GOMS更新）'!A:H,4,0) -> DE | F32: =VLOOKUP(B32,'大货清单（不定期按GOMS更新）'!A:H,2,0) -> Floor One Station S9 Scientist | G32: =VLOOKUP(B32,'大货清单（不定期按GOMS更新）'!A:I,9,FALSE) -> 6971745581557 | H32: =VLOOKUP(B32,'大货清单（不定期按GOMS更新）'!A:H,7,0) -> Gray | I32: =VLOOKUP(B32,'大货清单（不定期按GOMS更新）'!A:F,6,FALSE) -> GTM | J32: =VLOOKUP(B32,'大货清单（不定期按GOMS更新）'!A:K,11,FALSE) -> 14.3 | K32: =VLOOKUP(B32,'大货清单（不定期按GOMS更新）'!A:N,12,FALSE) -> 785 | L32: =VLOOKUP(B32,'大货清单（不定期按GOMS更新）'!A:M,13,FALSE) -> 386 | M32: =VLOOKUP(B32,'大货清单（不定期按GOMS更新）'!A:N,14,FALSE) -> 367 | N32: 9FWRP060500 | O32: =IFERROR(VLOOKUP(N32,'散件迭代（不定期更新）'!C:J,8,FALSE),0) -> 0 | P32: =IFERROR(VLOOKUP(N32,'散件（更新）'!B:H,3,FALSE),0) | Q32: =VLOOKUP(N32,'散件（更新）'!B:H,2,FALSE) -> 114-23761821 | R32: =VLOOKUP(N32,'散件（更新）'!B:H,7,FALSE) -> PCBA | S32: =VLOOKUP(N32,'散件（更新）'!B:E,4,FALSE) -> https://tineco-yxzt.oss-accelerate.aliyuncs.com/20241219/wifi_1734594448888.jpg | U32: =VLOOKUP(N32,'散件（更新）'!B:G,6,FALSE) -> WIFI 小板 | V32: =VLOOKUP(N32,'散件（更新）'!B:I,8,FALSE) -> 6932485002597
A33: 46169 | B33: FW770100DE | C33: =VLOOKUP(B33,'大货清单（不定期按GOMS更新）'!A:H,8,0) -> 109-24281001 | D33: =VLOOKUP(B33,'大货清单（不定期按GOMS更新）'!A:C,3,0) -> CL2428J-01 | E33: =VLOOKUP(B33,'大货清单（不定期按GOMS更新）'!A:H,4,0) -> DE | F33: =VLOOKUP(B33,'大货清单（不定期按GOMS更新）'!A:H,2,0) -> Floor One Station S9 Scientist | G33: =VLOOKUP(B33,'大货清单（不定期按GOMS更新）'!A:I,9,FALSE) -> 6971745581557 | H33: =VLOOKUP(B33,'大货清单（不定期按GOMS更新）'!A:H,7,0) -> Gray | I33: =VLOOKUP(B33,'大货清单（不定期按GOMS更新）'!A:F,6,FALSE) -> GTM | J33: =VLOOKUP(B33,'大货清单（不定期按GOMS更新）'!A:K,11,FALSE) -> 14.3 | K33: =VLOOKUP(B33,'大货清单（不定期按GOMS更新）'!A:N,12,FALSE) -> 785 | L33: =VLOOKUP(B33,'大货清单（不定期按GOMS更新）'!A:M,13,FALSE) -> 386 | M33: =VLOOKUP(B33,'大货清单（不定期按GOMS更新）'!A:N,14,FALSE) -> 367 | N33: 9FWRP0608AE | O33: =IFERROR(VLOOKUP(N33,'散件迭代（不定期更新）'!C:J,8,FALSE),0) -> 0 | P33: =IFERROR(VLOOKUP(N33,'散件（更新）'!B:H,3,FALSE),0) -> 0 | Q33: =VLOOKUP(N33,'散件（更新）'!B:H,2,FALSE) -> 114-23761847 | R33: =VLOOKUP(N33,'散件（更新）'!B:H,7,FALSE) -> PCBA | S33: =VLOOKUP(N33,'散件（更新）'!B:E,4,FALSE) -> 0 | U33: =VLOOKUP(N33,'散件（更新）'!B:G,6,FALSE) -> SP;CL2376R-03;WIFI小板 | V33: =VLOOKUP(N33,'散件（更新）'!B:I,8,FALSE) -> 6932485007325
... A49: 46169 | B49: FW770100DE | C49: =VLOOKUP(B49,'大货清单（不定期按GOMS更新）'!A:H,8,0) -> 109-24281001 | D49: =VLOOKUP(B49,'大货清单（不定期按GOMS更新）'!A:C,3,0) -> CL2428J-01 | E49: =VLOOKUP(B49,'大货清单（不定期按GOMS更新）'!A:H,4,0) -> DE | F49: =VLOOKUP(B49,'大货清单（不定期按GOMS更新）'!A:H,2,0) -> Floor One Station S9 Scientist | G49: =VLOOKUP(B49,'大货清单（不定期按GOMS更新）'!A:I,9,FALSE) -> 6971745581557 | H49: =VLOOKUP(B49,'大货清单（不定期按GOMS更新）'!A:H,7,0) -> Gray | I49: =VLOOKUP(B49,'大货清单（不定期按GOMS更新）'!A:F,6,FALSE) -> GTM | J49: =VLOOKUP(B49,'大货清单（不定期按GOMS更新）'!A:K,11,FALSE) -> 14.3 | K49: =VLOOKUP(B49,'大货清单（不定期按GOMS更新）'!A:N,12,FALSE) -> 785 | L49: =VLOOKUP(B49,'大货清单（不定期按GOMS更新）'!A:M,13,FALSE) -> 386 | M49: =VLOOKUP(B49,'大货清单（不定期按GOMS更新）'!A:N,14,FALSE) -> 367 | N49: 9FWWC510100 | O49: =IFERROR(VLOOKUP(N49,'散件迭代（不定期更新）'!C:J,8,FALSE),0) -> 0 | P49: =IFERROR(VLOOKUP(N49,'散件（更新）'!B:H,3,FALSE),0) | Q49: =VLOOKUP(N49,'散件（更新）'!B:H,2,FALSE) -> 114-24280326 | R49: =VLOOKUP(N49,'散件（更新）'!B:H,7,FALSE) -> Wiper Assembly | S49: =VLOOKUP(N49,'散件（更新）'!B:E,4,FALSE) -> https://tineco-yxzt.oss-accelerate.aliyuncs.com/20260210/rongyetongguashuizujian_1770686611562.png | U49: =VLOOKUP(N49,'散件（更新）'!B:G,6,FALSE) -> SP;CL2428C-01;溶液桶刮水组件 | V49: =VLOOKUP(N49,'散件（更新）'!B:I,8,FALSE) -> 6932485020867
A50: 46169 | B50: FW770100DE | C50: =VLOOKUP(B50,'大货清单（不定期按GOMS更新）'!A:H,8,0) -> 109-24281001 | D50: =VLOOKUP(B50,'大货清单（不定期按GOMS更新）'!A:C,3,0) -> CL2428J-01 | E50: =VLOOKUP(B50,'大货清单（不定期按GOMS更新）'!A:H,4,0) -> DE | F50: =VLOOKUP(B50,'大货清单（不定期按GOMS更新）'!A:H,2,0) -> Floor One Station S9 Scientist | G50: =VLOOKUP(B50,'大货清单（不定期按GOMS更新）'!A:I,9,FALSE) -> 6971745581557 | H50: =VLOOKUP(B50,'大货清单（不定期按GOMS更新）'!A:H,7,0) -> Gray | I50: =VLOOKUP(B50,'大货清单（不定期按GOMS更新）'!A:F,6,FALSE) -> GTM | J50: =VLOOKUP(B50,'大货清单（不定期按GOMS更新）'!A:K,11,FALSE) -> 14.3 | K50: =VLOOKUP(B50,'大货清单（不定期按GOMS更新）'!A:N,12,FALSE) -> 785 | L50: =VLOOKUP(B50,'大货清单（不定期按GOMS更新）'!A:M,13,FALSE) -> 386 | M50: =VLOOKUP(B50,'大货清单（不定期按GOMS更新）'!A:N,14,FALSE) -> 367 | N50: 9FWWC540000 | O50: =IFERROR(VLOOKUP(N50,'散件迭代（不定期更新）'!C:J,8,FALSE),0) -> 0 | P50: =IFERROR(VLOOKUP(N50,'散件（更新）'!B:H,3,FALSE),0) | Q50: =VLOOKUP(N50,'散件（更新）'!B:H,2,FALSE) -> 114-25390615 | R50: =VLOOKUP(N50,'散件（更新）'!B:H,7,FALSE) -> Water Tank On The Charging Base | S50: =VLOOKUP(N50,'散件（更新）'!B:E,4,FALSE) -> https://tineco-yxzt.oss-accelerate.aliyuncs.com/20260206/tuopanshuixiangzujian_1770359718408.JPG | T50: for brush | U50: =VLOOKUP(N50,'散件（更新）'!B:G,6,FALSE) -> SP;CL2539F-01;托盘水箱组件 | V50: =VLOOKUP(N50,'散件（更新）'!B:I,8,FALSE) -> 6932485021536
A51: 46169 | B51: FW770100DE | C51: =VLOOKUP(B51,'大货清单（不定期按GOMS更新）'!A:H,8,0) -> 109-24281001 | D51: =VLOOKUP(B51,'大货清单（不定期按GOMS更新）'!A:C,3,0) -> CL2428J-01 | E51: =VLOOKUP(B51,'大货清单（不定期按GOMS更新）'!A:H,4,0) -> DE | F51: =VLOOKUP(B51,'大货清单（不定期按GOMS更新）'!A:H,2,0) -> Floor One Station S9 Scientist | G51: =VLOOKUP(B51,'大货清单（不定期按GOMS更新）'!A:I,9,FALSE) -> 6971745581557 | H51: =VLOOKUP(B51,'大货清单（不定期按GOMS更新）'!A:H,7,0) -> Gray | I51: =VLOOKUP(B51,'大货清单（不定期按GOMS更新）'!A:F,6,FALSE) -> GTM | J51: =VLOOKUP(B51,'大货清单（不定期按GOMS更新）'!A:K,11,FALSE) -> 14.3 | K51: =VLOOKUP(B51,'大货清单（不定期按GOMS更新）'!A:N,12,FALSE) -> 785 | L51: =VLOOKUP(B51,'大货清单（不定期按GOMS更新）'!A:M,13,FALSE) -> 386 | M51: =VLOOKUP(B51,'大货清单（不定期按GOMS更新）'!A:N,14,FALSE) -> 367 | N51: 9FWWD510000 | O51: =IFERROR(VLOOKUP(N51,'散件迭代（不定期更新）'!C:J,8,FALSE),0) -> 0 | P51: =IFERROR(VLOOKUP(N51,'散件（更新）'!B:H,3,FALSE),0) | Q51: =VLOOKUP(N51,'散件（更新）'!B:H,2,FALSE) -> 114-24280302 | R51: =VLOOKUP(N51,'散件（更新）'!B:H,7,FALSE) -> Dirt Water Tank | S51: =VLOOKUP(N51,'散件（更新）'!B:E,4,FALSE) -> https://tineco-yxzt.oss-accelerate.aliyuncs.com/20260210/huishoutongzujian_1770685404443.png | T51: for main body | U51: =VLOOKUP(N51,'散件（更新）'!B:G,6,FALSE) -> SP;CL2428C-01;回收桶组件 | V51: =VLOOKUP(N51,'散件（更新）'!B:I,8,FALSE) -> 6932485020621
A52: 46169 | B52: FW770100DE | C52: =VLOOKUP(B52,'大货清单（不定期按GOMS更新）'!A:H,8,0) -> 109-24281001 | D52: =VLOOKUP(B52,'大货清单（不定期按GOMS更新）'!A:C,3,0) -> CL2428J-01 | E52: =VLOOKUP(B52,'大货清单（不定期按GOMS更新）'!A:H,4,0) -> DE | F52: =VLOOKUP(B52,'大货清单（不定期按GOMS更新）'!A:H,2,0) -> Floor One Station S9 Scientist | G52: =VLOOKUP(B52,'大货清单（不定期按GOMS更新）'!A:I,9,FALSE) -> 6971745581557 | H52: =VLOOKUP(B52,'大货清单（不定期按GOMS更新）'!A:H,7,0) -> Gray | I52: =VLOOKUP(B52,'大货清单（不定期按GOMS更新）'!A:F,6,FALSE) -> GTM | J52: =VLOOKUP(B52,'大货清单（不定期按GOMS更新）'!A:K,11,FALSE) -> 14.3 | K52: =VLOOKUP(B52,'大货清单（不定期按GOMS更新）'!A:N,12,FALSE) -> 785 | L52: =VLOOKUP(B52,'大货清单（不定期按GOMS更新）'!A:M,13,FALSE) -> 386 | M52: =VLOOKUP(B52,'大货清单（不定期按GOMS更新）'!A:N,14,FALSE) -> 367 | N52: 9FWWD510100 | O52: =IFERROR(VLOOKUP(N52,'散件迭代（不定期更新）'!C:J,8,FALSE),0) -> 0 | P52: =IFERROR(VLOOKUP(N52,'散件（更新）'!B:H,3,FALSE),0) | Q52: =VLOOKUP(N52,'散件（更新）'!B:H,2,FALSE) -> 114-24280303 | R52: =VLOOKUP(N52,'散件（更新）'!B:H,7,FALSE) -> DWT Cover | S52: =VLOOKUP(N52,'散件（更新）'!B:E,4,FALSE) -> https://tineco-yxzt.oss-accelerate.aliyuncs.com/20260210/DWTcover_1770685470188.png | T52: for main body | U52: =VLOOKUP(N52,'散件（更新）'!B:G,6,FALSE) -> SP;CL2428C-01;回收桶盖组件 | V52: =VLOOKUP(N52,'散件（更新）'!B:I,8,FALSE) -> 6932485020638
A53: 46169 | B53: FW770100DE | C53: =VLOOKUP(B53,'大货清单（不定期按GOMS更新）'!A:H,8,0) -> 109-24281001 | D53: =VLOOKUP(B53,'大货清单（不定期按GOMS更新）'!A:C,3,0) -> CL2428J-01 | E53: =VLOOKUP(B53,'大货清单（不定期按GOMS更新）'!A:H,4,0) -> DE | F53: =VLOOKUP(B53,'大货清单（不定期按GOMS更新）'!A:H,2,0) -> Floor One Station S9 Scientist | G53: =VLOOKUP(B53,'大货清单（不定期按GOMS更新）'!A:I,9,FALSE) -> 6971745581557 | H53: =VLOOKUP(B53,'大货清单（不定期按GOMS更新）'!A:H,7,0) -> Gray | I53: =VLOOKUP(B53,'大货清单（不定期按GOMS更新）'!A:F,6,FALSE) -> GTM | J53: =VLOOKUP(B53,'大货清单（不定期按GOMS更新）'!A:K,11,FALSE) -> 14.3 | K53: =VLOOKUP(B53,'大货清单（不定期按GOMS更新）'!A:N,12,FALSE) -> 785 | L53: =VLOOKUP(B53,'大货清单（不定期按GOMS更新）'!A:M,13,FALSE) -> 386 | M53: =VLOOKUP(B53,'大货清单（不定期按GOMS更新）'!A:N,14,FALSE) -> 367 | N53: 9FWWD510200 | O53: =IFERROR(VLOOKUP(N53,'散件迭代（不定期更新）'!C:J,8,FALSE),0) -> 0 | P53: =IFERROR(VLOOKUP(N53,'散件（更新）'!B:H,3,FALSE),0) | Q53: =VLOOKUP(N53,'散件（更新）'!B:H,2,FALSE) -> 114-24280322 | R53: =VLOOKUP(N53,'散件（更新）'!B:H,7,FALSE) -> DWT Body | S53: =VLOOKUP(N53,'散件（更新）'!B:E,4,FALSE) -> 0 | T53: for charging base | U53: =VLOOKUP(N53,'散件（更新）'!B:G,6,FALSE) -> SP;CL2428C-01;回收桶桶体 | V53: =VLOOKUP(N53,'散件（更新）'!B:I,8,FALSE) -> 6932485020829
A54: 46169 | B54: FW770100DE | C54: =VLOOKUP(B54,'大货清单（不定期按GOMS更新）'!A:H,8,0) -> 109-24281001 | D54: =VLOOKUP(B54,'大货清单（不定期按GOMS更新）'!A:C,3,0) -> CL2428J-01 | E54: =VLOOKUP(B54,'大货清单（不定期按GOMS更新）'!A:H,4,0) -> DE | F54: =VLOOKUP(B54,'大货清单（不定期按GOMS更新）'!A:H,2,0) -> Floor One Station S9 Scientist | G54: =VLOOKUP(B54,'大货清单（不定期按GOMS更新）'!A:I,9,FALSE) -> 6971745581557 | H54: =VLOOKUP(B54,'大货清单（不定期按GOMS更新）'!A:H,7,0) -> Gray | I54: =VLOOKUP(B54,'大货清单（不定期按GOMS更新）'!A:F,6,FALSE) -> GTM | J54: =VLOOKUP(B54,'大货清单（不定期按GOMS更新）'!A:K,11,FALSE) -> 14.3 | K54: =VLOOKUP(B54,'大货清单（不定期按GOMS更新）'!A:N,12,FALSE) -> 785 | L54: =VLOOKUP(B54,'大货清单（不定期按GOMS更新）'!A:M,13,FALSE) -> 386 | M54: =VLOOKUP(B54,'大货清单（不定期按GOMS更新）'!A:N,14,FALSE) -> 367 | N54: 9SWRH150200 | O54: =IFERROR(VLOOKUP(N54,'散件迭代（不定期更新）'!C:J,8,FALSE),0) -> 0 | P54: =IFERROR(VLOOKUP(N54,'散件（更新）'!B:H,3,FALSE),0) -> 0 | Q54: =VLOOKUP(N54,'散件（更新）'!B:H,2,FALSE) -> 114-25010014 | R54: =VLOOKUP(N54,'散件（更新）'!B:H,7,FALSE) -> plastic part | S54: =VLOOKUP(N54,'散件（更新）'!B:E,4,FALSE) -> https://tineco-yxzt.oss-accelerate.aliyuncs.com/20250828/guatiaosuokou_1756372355135.jpg | T54: wifi PCBA | U54: =VLOOKUP(N54,'散件（更新）'!B:G,6,FALSE) -> SP;CL2501-01;刮条锁扣 | V54: =VLOOKUP(N54,'散件（更新）'!B:I,8,FALSE) -> 6932485010950
A55: 46169 | B55: FW770100DE | C55: =VLOOKUP(B55,'大货清单（不定期按GOMS更新）'!A:H,8,0) -> 109-24281001 | D55: =VLOOKUP(B55,'大货清单（不定期按GOMS更新）'!A:C,3,0) -> CL2428J-01 | E55: =VLOOKUP(B55,'大货清单（不定期按GOMS更新）'!A:H,4,0) -> DE | F55: =VLOOKUP(B55,'大货清单（不定期按GOMS更新）'!A:H,2,0) -> Floor One Station S9 Scientist | G55: =VLOOKUP(B55,'大货清单（不定期按GOMS更新）'!A:I,9,FALSE) -> 6971745581557 | H55: =VLOOKUP(B55,'大货清单（不定期按GOMS更新）'!A:H,7,0) -> Gray | I55: =VLOOKUP(B55,'大货清单（不定期按GOMS更新）'!A:F,6,FALSE) -> GTM | J55: =VLOOKUP(B55,'大货清单（不定期按GOMS更新）'!A:K,11,FALSE) -> 14.3 | K55: =VLOOKUP(B55,'大货清单（不定期按GOMS更新）'!A:N,12,FALSE) -> 785 | L55: =VLOOKUP(B55,'大货清单（不定期按GOMS更新）'!A:M,13,FALSE) -> 386 | M55: =VLOOKUP(B55,'大货清单（不定期按GOMS更新）'!A:N,14,FALSE) -> 367 | N55: 9SWRR150000 | O55: =IFERROR(VLOOKUP(N55,'散件迭代（不定期更新）'!C:J,8,FALSE),0) -> 0 | P55: =IFERROR(VLOOKUP(N55,'散件（更新）'!B:H,3,FALSE),0) -> 0 | Q55: =VLOOKUP(N55,'散件（更新）'!B:H,2,FALSE) -> 114-25010013 | R55: =VLOOKUP(N55,'散件（更新）'!B:H,7,FALSE) -> Scraper | S55: =VLOOKUP(N55,'散件（更新）'!B:E,4,FALSE) -> https://tineco-yxzt.oss-accelerate.aliyuncs.com/20250828/kechaiguatiaozujian_1756372187799.jpg | U55: =VLOOKUP(N55,'散件（更新）'!B:G,6,FALSE) -> SP;CL2501-01;可拆刮条组件 | V55: =VLOOKUP(N55,'散件（更新）'!B:I,8,FALSE) -> 6932485010943
A56: 46169 | B56: FW310300DE | C56: =VLOOKUP(B56,'大货清单（不定期按GOMS更新）'!A:H,8,0) -> 109-23480601 | D56: =VLOOKUP(B56,'大货清单（不定期按GOMS更新）'!A:C,3,0) -> CL2348F-01 | E56: =VLOOKUP(B56,'大货清单（不定期按GOMS更新）'!A:H,4,0) -> DE,FR,SE,PL,BE,NL,ES,IT,MN,ZA,PE,CL | F56: =VLOOKUP(B56,'大货清单（不定期按GOMS更新）'!A:H,2,0) -> FLOOR ONE SWITCH S6 STRETCH | G56: =VLOOKUP(B56,'大货清单（不定期按GOMS更新）'!A:I,9,FALSE) -> 6932485002290 | H56: =VLOOKUP(B56,'大货清单（不定期按GOMS更新）'!A:H,7,0) -> WHITE&BLACK | I56: =VLOOKUP(B56,'大货清单（不定期按GOMS更新）'!A:F,6,FALSE) -> ACTIVE | J56: =VLOOKUP(B56,'大货清单（不定期按GOMS更新）'!A:K,11,FALSE) -> 12.6 | K56: =VLOOKUP(B56,'大货清单（不定期按GOMS更新）'!A:N,12,FALSE) -> 850 | L56: =VLOOKUP(B56,'大货清单（不定期按GOMS更新）'!A:M,13,FALSE) -> 332 | M56: =VLOOKUP(B56,'大货清单（不定期按GOMS更新）'!A:N,14,FALSE) -> 318 | N56: 9FWBP3100SA | O56: =IFERROR(VLOOKUP(N56,'散件迭代（不定期更新）'!C:J,8,FALSE),0) -> 0 | P56: =IFERROR(VLOOKUP(N56,'散件（更新）'!B:H,3,FALSE),0) -> 0 | Q56: =VLOOKUP(N56,'散件（更新）'!B:H,2,FALSE) -> 114-23481211 | R56: =VLOOKUP(N56,'散件（更新）'!B:H,7,FALSE) -> Carpet Brush | S56: =VLOOKUP(N56,'散件（更新）'!B:E,4,FALSE) -> https://tineco-yxzt.oss-accelerate.aliyuncs.com/20250521/11-carpetbrush_1747825031321.png | T56: water sensor | U56: =VLOOKUP(N56,'散件（更新）'!B:G,6,FALSE) -> SP;CL2348L-02;地刷组件（沙特FB2116A带PTC） | V56: =VLOOKUP(N56,'散件（更新）'!B:I,8,FALSE) -> 6932485008070
A57: 46169 | B57: FW251800DE | C57: =VLOOKUP(B57,'大货清单（不定期按GOMS更新）'!A:H,8,0) -> 109-22200803 | D57: =VLOOKUP(B57,'大货清单（不定期按GOMS更新）'!A:C,3,0) -> CL2220H-03 | E57: =VLOOKUP(B57,'大货清单（不定期按GOMS更新）'!A:H,4,0) -> ES,DE,PL,FR,NL,RO,LT,DK,IT,UA | F57: =VLOOKUP(B57,'大货清单（不定期按GOMS更新）'!A:H,2,0) -> Floor One Switch S7 Pet | G57: =VLOOKUP(B57,'大货清单（不定期按GOMS更新）'!A:I,9,FALSE) -> 6974950108274,'6974950108274, 6974950108274 | H57: =VLOOKUP(B57,'大货清单（不定期按GOMS更新）'!A:H,7,0) -> Blue | I57: =VLOOKUP(B57,'大货清单（不定期按GOMS更新）'!A:F,6,FALSE) -> ACTIVE | J57: =VLOOKUP(B57,'大货清单（不定期按GOMS更新）'!A:K,11,FALSE) -> 15.8 | K57: =VLOOKUP(B57,'大货清单（不定期按GOMS更新）'!A:N,12,FALSE) -> 845 | L57: =VLOOKUP(B57,'大货清单（不定期按GOMS更新）'!A:M,13,FALSE) -> 382 | M57: =VLOOKUP(B57,'大货清单（不定期按GOMS更新）'!A:N,14,FALSE) -> 410 | N57: 9FWRH250200 | O57: =IFERROR(VLOOKUP(N57,'散件迭代（不定期更新）'!C:J,8,FALSE),0) -> 0 | P57: =IFERROR(VLOOKUP(N57,'散件（更新）'!B:H,3,FALSE),0) | Q57: =VLOOKUP(N57,'散件（更新）'!B:H,2,FALSE) -> 114-22200711 | R57: =VLOOKUP(N57,'散件（更新）'!B:H,7,FALSE) -> Lower Decorative Cover | S57: =VLOOKUP(N57,'散件（更新）'!B:E,4,FALSE) -> https://tineco-yxzt.oss-accelerate.aliyuncs.com/20251117/794aaca7-6daa-4914-a742-ef353b11b687_1763342025355.png | T57: for main body | U57: =VLOOKUP(N57,'散件（更新）'!B:G,6,FALSE) -> SP;CL2220G-01;机体下装饰盖 | V57: =VLOOKUP(N57,'散件（更新）'!B:I,8,FALSE) -> 6932485017997
...

Sheet Refurbished FG list
A1: Refurbished SKU | B1: NAME | C1: Area | D1: Refurbished SAP ID | E1: EAN
A2: FW0501A0EU | B2: Floor One S3 | C2: EU | D2: 109-18790001-A | E2: 6932485014422
A3: FW0501B0EU | B3: Floor One S3 | C3: EU | D3: 109-18790001-B | E3: 6932485014439
A4: FW0507A0DE | B4: Floor One S3 Extreme | C4: EU | D4: 109-18790009-A | E4: 6932485014446
A5: FW0507B0DE | B5: Floor One S3 Extreme | C5: EU | D5: 109-18790009-B | E5: 6932485014453
A6: FW0301A0EU | B6: iFloor 3 | C6: EU | D6: 109-18790501-A | E6: 6932485014460
A7: FW0301B0EU | B7: iFloor 3 | C7: EU | D7: 109-18790501-B | E7: 6932485014477
A8: FW0306A0DE | B8: iFloor 3 Plus | C8: EU | D8: 109-18790505-A | E8: 6932485014484
A9: FW0306B0DE | B9: iFloor 3 Plus | C9: EU | D9: 109-18790505-B | E9: 6932485014491
A10: FW0401A0EU | B10: iFloor Breeze | C10: EU | D10: 109-20110401-A | E10: 6932485014507
A11: FW0401B0EU | B11: iFloor Breeze | C11: EU | D11: 109-20110401-B | E11: 6932485014514
A12: FW0406A0EU | B12: iFloor 3 Breeze Plus | C12: EU | D12: 109-20110406-A | E12: 6932485014521
A13: FW0406B0EU | B13: iFloor 3 Breeze Plus | C13: EU | D13: 109-20110406-B | E13: 6932485014538
... A264: FW2E02A0DE | B264: Floor One S9 Artist Elite | C264: EU | D264: 109-25810002-A | E264: 6932485023318
A265: VS1B09A0DE | B265: PURE ONE STATION PET | C265: EU | D265: 107-22251401-A
A266: VS1B09B0DE | B266: PURE ONE STATION PET | C266: EU | D266: 107-22251401-B
A267: VS2602B0DE | B267: PURE ONE A70S | C267: EU | D267: 107-25600002-B
A268: FW1038A0EU | B268: Floor One S5 Extreme | C268: EU | D268: 109-20191902-A
A269: FW1038B0EU | B269: Floor One S5 Extreme | C269: EU | D269: 109-20191902-B
A270: FW7701A0DE | B270: Floor One Station S9 Scientist | C270: EU | D270: 109-24281001-A
A271: FW7701B0DE | B271: Floor One Station S9 Scientist | C271: EU | D271: 109-24281001-B
A272: FW3420A0DE | B272: Floor One Stretch S6 Combo | C272: EU | D272: 109-25430202-A
A273: FW3420B0DE | B273: Floor One Stretch S6 Combo | C273: EU | D273: 109-25430202-B
A274: FW7801A0DE | B274: Floor One S9 Artist Boost Steam Premium | C274: EU | D274: 109-26150001-A
A275: FW7801B0DE | B275: Floor One S9 Artist Boost Steam Premium | C275: EU | D275: 109-26150001-B
A276: FW7802A0DE | B276: Floor One S9 Artist Boost Steam | C276: EU | D276: 109-26150002-A
A277: FW7802B0DE | B277: Floor One S9 Artist Boost Steam | C277: EU | D277: 109-26150002-B

Sheet 大货清单（不定期按GOMS更新）
A1: 产品SKU | B1: 产品名称 | C1: 产品系列型号 | D1: 国家 | E1: 渠道大类 | F1: 产品状态(更新) | G1: 产品颜色 | H1: 产品SAP ID | I1: 商品流通码EAN/EAN | J1: 商品流通码UPC(NA)/UPC | K1: 箱毛重KG/Gross weight | L1: 外箱包装尺寸(MM)长/Package MM Length | M1: 外箱包装尺寸(MM)宽/Package MM Width | N1: 外箱包装尺寸(MM)高/Package MM Height | O1: 备注 | P1: 检查list | Q1: 来源：产品档案
A2: VA110000EU | B2: A11 Hero | C2: ZB1769U-01 | D2: 0 | E2: OFFLINE | F2: PHASEOUT | G2: Moonstone | H2: 165-1769-2101,107-17692101 | I2: 6972200192752 | J2: 0 | K2: 6.15 | L2: 756 | M2: 154 | N2: 279
A3: FW102400UK | B3: Floor One S5 Extreme | C3: CL2019F-06 | D3: IE,GB | E3: OFFLINE,ONLINE | F3: PHASEOUT | G3: Blue | H3: 109-20190606 | I3: 6972200199249 | J3: /, | K3: 8.2 | L3: 326 | M3: 296 | N3: 672
A4: UKA111MOO | B4: A11 Hero | C4: ZB1769-01 | D4: 0 | F4: PHASEOUT | G4: Moonstone | H4: 107-17690001 | I4: #N/A | J4: 0 | K4: 6.9 | L4: 784 | M4: 180 | N4: 326
A5: FW1B0200US | B5: GO H2O-GH203 | C5: CL2315G-02 | D5: US | E5: OFFLINE | F5: ACTIVE | G5: White/light blue | H5: 109-23150702 | I5: #N/A | J5: 194846101462 | K5: 9.04 | L5: 722 | M5: 326 | N5: 289
A6: FW007700US | B6: Floor One S3 Complete | C6: CL2011F-02 | D6: US | E6: ONLINE | F6: PHASEOUT | G6: Black | H6: 109-20110602 | I6: #N/A | J6: 194846100816 | K6: 8.6 | L6: 326 | M6: 296 | N6: 672
A7: FW040100US | B7: iFloor 3 Breeze | C7: CL2011A-01 | D7: US,MX,NI,CA | E7: OFFLINE,ONLINE | F7: ACTIVE | G7: White&Grey | H7: 109-20110101 | I7: #N/A | J7: 194846100199 | K7: 7.4 | L7: 326 | M7: 296 | N7: 672
A8: JPA103GRY | B8: A10 Danimo | C8: ZB1756C-03 | D8: 0 | F8: PHASEOUT | G8: Metallic Grey | H8: 107-17560303 | I8: #N/A | J8: 0 | K8: 0 | L8: 0 | M8: 0 | N8: 0
A9: FW030900VN | B9: iFloor 3 | C9: CL1879E-07 | D9: VN | E9: OFFLINE | F9: PHASEOUT | G9: White&Grey | H9: 109-18790507 | I9: 6972200199447 | J9: / | K9: 9.1 | L9: 743 | M9: 330 | N9: 300
A10: FW050100EU | B10: Floor One S3 | C10: CL1879-01 | D10: CL,FR,IT,UA,ES,DE,AT,CH,TR,SE,PL,NL,BE | E10: OFFLINE,ONLINE | F10: PHASEOUT | G10: Black | H10: 109-18790001 | I10: 6972200190512 | J10: /, | K10: 8 | L10: 326 | M10: 296 | N10: 736
A11: FW040600EU | B11: iFloor 3 Breeze Plus | C11: CL2011D-06 | D11: DE,FR,IT,ES,NL,PL,SE,BE | E11: ONLINE | F11: ACTIVE | G11: White&Grey | H11: 109-20110406 | I11: 6972200199225 | J11: / | K11: 7.5 | L11: 326 | M11: 296 | N11: 672
A12: VA101100US | B12: A10 Spartan | C12: ZB1756D-06 | D12: CA,US | E12: OFFLINE,ONLINE | F12: PHASEOUT | G12: Metallic Grey | H12: 107-17560406 | I12: #N/A | J12: 194846000857 | K12: 4.7 | L12: 756 | M12: 154 | N12: 279
A13: FW030100UK | B13: iFloor 3 | C13: CL1879E-02 | D13: GB,AE,FR | E13: ONLINE | F13: PHASEOUT | G13: White&Grey | H13: 109-18790502 | I13: 6972200192158 | J13: / | K13: 8 | L13: 326 | M13: 296 | N13: 736
A14: FW104000VN | B14: Floor One S5 | C14: CL2019V-01 | D14: VN | E14: OFFLINE | F14: PHASEOUT | G14: black | H14: 109-20192201 | I14: 6974950102272 | J14: 0 | K14: 8.5 | L14: 334 | M14: 304 | N14: 683
A15: EUS123GRY | B15: PURE ONE S12 PLUS | C15: ZB1873G-03 | D15: 0 | F15: PHASEOUT | G15: Metallic Grey | H15: 107-18730703 | I15: #N/A | J15: 0 | K15: 8.2 | L15: 840 | M15: 163 | N15: 394
A16: HD050200UK | B16: MODA ONE | C16: CD1960D-05 | D16: GB | E16: ONLINE | F16: CANCEL | G16: Cream | H16: 111-19600405 | I16: 6972200192400 | J16: / | K16: 8.57 | L16: 267 | M16: 368 | N16: 402
A17: FW103200US | B17: Floor One S5 Pro 2 | C17: CL2019Q-01 | D17: US | E17: ONLINE | F17: PHASEOUT | G17: black | H17: 109-20191701 | I17: #N/A | J17: 194846100601 | K17: 8 | L17: 326 | M17: 296 | N17: 672
A18: FW202500RU | B18: FLOOR ONE S7 PRO | C18: CL2123Q-01 | D18: RU | E18: OFFLINE | F18: PHASEOUT | G18: Black | H18: 109-21231701 | I18: 6974950104405 | J18: / | K18: 9.7 | L18: 674 | M18: 332 | N18: 306
A19: FW030100PH | B19: iFloor 3 | C19: CL1879D-04 | D19: PH | E19: ONLINE | F19: PHASEOUT | G19: White&Grey | H19: 109-18790404 | I19: 6972200195180 | J19: / | K19: 9.1 | L19: 334 | M19: 304 | N19: 748
A20: USA102BLU | B20: A10 Hero | C20: ZB1756B-05 | D20: 0 | F20: PHASEOUT | G20: Space Blue | H20: 107-17560205 | I20: #N/A | J20: / | K20: 0 | L20: 0 | M20: 0 | N20: 0
A21: SW110600DE | B21: Floor One S7 Steam Plus | C21: CL2203B-02 | D21: ES,DE,AT,CH,NL,FR,RO,DK,GR,IT,UA,HK | E21: OFFLINE | F21: ACTIVE | G21: White&Black | H21: 109-22030202 | I21: 6974950102234, 6974950102234, 6974950102234 | J21: / | K21: 9.6 | L21: 765 | M21: 330 | N21: 322
A22: VA101000EU | B22: A10 Hero | C22: ZB1756U-02 | D22: UA,DE,FR,CH,AT,ES,IT,NL,PL,SE,MN | E22: OFFLINE,ONLINE | F22: PHASEOUT | G22: Space Blue | H22: 107-17562102 | I22: 6972200192714 | J22: / | K22: 5 | L22: 756 | M22: 154 | N22: 279
A23: VS040400MY | B23: PURE ONE Mini S4 | C23: ZB1980H-05 | D23: MY,SG | E23: OFFLINE | F23: PHASEOUT | G23: White | H23: 107-19800805 | I23: 6972200199416 | J23: / | K23: 9.2 | L23: 494 | M23: 298 | N23: 462
A24: JPA102BLU | B24: A10 Hero | C24: ZB1756C-01 | D24: 0 | F24: PHASEOUT | G24: Space Blue | H24: 107-17560301 | I24: #N/A | J24: / | K24: 0 | L24: 0 | M24: 0 | N24: 0
A25: VA101000AU | B25: A10 Hero | C25: ZB1756L-01 | D25: AU | E25: OFFLINE,ONLINE | F25: PHASEOUT | G25: Space Blue | H25: 107-17561201 | I25: 6972200192646 | J25: / | K25: 5 | L25: 756 | M25: 154 | N25: 279 | O25: 老品不维护
A26: CW101800SA | B26: Carpet One | C26: CL2043K-01 | D26: AE,IQ | E26: OFFLINE | F26: ACTIVE | G26: Black | H26: 108-20431101 | I26: 6974950103323 | J26: / | K26: 13.4 | L26: 473 | M26: 346 | N26: 702
A27: FW104300SA | B27: Floor One S5 | C27: CL2019W-01 | D27: AE,JO | E27: OFFLINE | F27: PHASEOUT | G27: Black | H27: 109-20192301 | I27: 6974950103682 | J27: / | K27: 8 | L27: 326 | M27: 296 | N27: 672
A28: VS1A0800US | B28: 0 | C28: ZB2225K-02 | D28: US | E28: OFFLINE | F28: CANCEL | G28: 0 | H28: 107-22251102 | I28: #N/A | J28: 194846002721 | K28: 14.1 | L28: 813 | M28: 380 | N28: 324 | O28: 不维护
A29: SW100800AU | B29: Floor One S5 Steam | C29: CL2029G-01 | D29: AU | E29: ONLINE | F29: ACTIVE | G29: White&Black | H29: 109-20290701 | I29: 6972200198853 | J29: / | K29: 9.8 | L29: 362 | M29: 336 | N29: 676
A30: FW150800IL | B30: Floor One S5 Combo | C30: CL2020H-09 | D30: IL | E30: OFFLINE | F30: PHASEOUT | G30: Black | H30: 109-20200809 | I30: 6972200199263 | J30: / | K30: 8.12 | L30: 326 | M30: 292 | N30: 661
A31: HD050400US | B31: MODA ONE | C31: CD1960B-07 | D31: CA,US | E31: OFFLINE,ONLINE | F31: PHASEOUT | G31: Red | H31: 111-19600207 | I31: #N/A | J31: 194846200103, 194846200103 | K31: 9.45 | L31: 384 | M31: 378 | N31: 367 | O31: 不维护
A32: A10US0A02 | B32: A10 Master | C32: ZB1756R-02 | D32: US | F32: PHASEOUT | G32: Grey | H32: 107-17561802 | I32: #N/A | J32: 194846000499 | K32: 5.88 | L32: 784 | M32: 180 | N32: 326
A33: FW102700TH | B33: Floor One S5 Pro 2 | C33: CL2019B-08 | D33: TH,VN,MN | E33: OFFLINE | F33: PHASEOUT | G33: Black | H33: 109-20190208 | I33: 6972200199454 | J33: / | K33: 8.5 | L33: 334 | M33: 304 | N33: 683
A34: VA117000US | B34: PWRHERO 11 ZT | C34: ZB2016F-07 | D34: US,CA | E34: OFFLINE | F34: ACTIVE | G34: Coffee | H34: 107-20160607 | I34: #N/A | J34: 194846002509 | K34: 4.76 | L34: 742 | M34: 155 | N34: 288
